{
  "version": 8,
  "blockIdVersion": 11,
  "anchorX": 55,
  "anchorY": 21,
  "anchorZ": 30,
  "blocks": [
    {
      "x": 49,
      "y": -9,
      "z": 24,
      "name": "Rock_Stone"
    },
    {
      "x": 49,
      "y": -8,
      "z": 24,
      "name": "Rock_Stone"
    },
    {
      "x": 49,
      "y": -7,
      "z": 24,
      "name": "Rock_Stone"
    },
    {
      "x": 49,
      "y": -6,
      "z": 24,
      "name": "Rock_Stone"
    },
    {
      "x": 49,
      "y": -5,
      "z": 24,
      "name": "Rock_Stone"
    },
    {
      "x": 49,
      "y": -4,
      "z": 24,
      "name": "Rock_Stone"
    },
    {
      "x": 49,
      "y": -3,
      "z": 24,
      "name": "Rock_Stone"
    },
    {
      "x": 49,
      "y": -2,
      "z": 24,
      "name": "Rock_Stone"
    },
    {
      "x": 49,
      "y": -1,
      "z": 24,
      "name": "Rock_Stone"
    },
    {
      "x": 49,
      "y": 0,
      "z": 24,
      "name": "Rock_Stone"
    },
    {
      "x": 49,
      "y": 1,
      "z": 24,
      "name": "Rock_Stone"
    },
    {
      "x": 49,
      "y": 2,
      "z": 24,
      "name": "Rock_Stone"
    },
    {
      "x": 49,
      "y": 3,
      "z": 24,
      "name": "Ore_Iron_Basalt"
    },
    {
      "x": 49,
      "y": 4,
      "z": 24,
      "name": "Rock_Basalt"
    },
    {
      "x": 49,
      "y": 5,
      "z": 24,
      "name": "Ore_Iron_Basalt"
    },
    {
      "x": 49,
      "y": 6,
      "z": 24,
      "name": "Rock_Stone"
    },
    {
      "x": 49,
      "y": 7,
      "z": 24,
      "name": "Soil_Gravel"
    },
    {
      "x": 49,
      "y": 8,
      "z": 24,
      "name": "Soil_Gravel"
    },
    {
      "x": 49,
      "y": 9,
      "z": 24,
      "name": "Rock_Stone"
    },
    {
      "x": 49,
      "y": 10,
      "z": 24,
      "name": "Rock_Basalt"
    },
    {
      "x": 49,
      "y": 11,
      "z": 24,
      "name": "Rock_Stone"
    },
    {
      "x": 49,
      "y": 12,
      "z": 24,
      "name": "Ore_Iron_Basalt_Cracked"
    },
    {
      "x": 49,
      "y": 13,
      "z": 24,
      "name": "Ore_Iron_Basalt_Cracked"
    },
    {
      "x": 49,
      "y": 14,
      "z": 24,
      "name": "Ore_Iron_Basalt_Cracked"
    },
    {
      "x": 49,
      "y": 15,
      "z": 24,
      "name": "Rock_Basalt"
    },
    {
      "x": 49,
      "y": 16,
      "z": 24,
      "name": "Rock_Basalt"
    },
    {
      "x": 49,
      "y": 17,
      "z": 24,
      "name": "Rock_Basalt"
    },
    {
      "x": 49,
      "y": 18,
      "z": 24,
      "name": "Rock_Basalt_Cobble"
    },
    {
      "x": 49,
      "y": 19,
      "z": 24,
      "name": "Soil_Gravel"
    },
    {
      "x": 49,
      "y": 20,
      "z": 24,
      "name": "Rock_Basalt"
    },
    {
      "x": 49,
      "y": 21,
      "z": 24,
      "name": "Rock_Stone"
    },
    {
      "x": 49,
      "y": -9,
      "z": 25,
      "name": "Rock_Stone"
    },
    {
      "x": 49,
      "y": -8,
      "z": 25,
      "name": "Rock_Stone"
    },
    {
      "x": 49,
      "y": -7,
      "z": 25,
      "name": "Rock_Stone"
    },
    {
      "x": 49,
      "y": -6,
      "z": 25,
      "name": "Rock_Stone"
    },
    {
      "x": 49,
      "y": -5,
      "z": 25,
      "name": "Rock_Stone"
    },
    {
      "x": 49,
      "y": -4,
      "z": 25,
      "name": "Rock_Stone"
    },
    {
      "x": 49,
      "y": -3,
      "z": 25,
      "name": "Rock_Stone"
    },
    {
      "x": 49,
      "y": -2,
      "z": 25,
      "name": "Rock_Stone"
    },
    {
      "x": 49,
      "y": -1,
      "z": 25,
      "name": "Rock_Stone"
    },
    {
      "x": 49,
      "y": 0,
      "z": 25,
      "name": "Rock_Stone"
    },
    {
      "x": 49,
      "y": 1,
      "z": 25,
      "name": "Rock_Stone"
    },
    {
      "x": 49,
      "y": 2,
      "z": 25,
      "name": "Rock_Stone"
    },
    {
      "x": 49,
      "y": 3,
      "z": 25,
      "name": "Rock_Basalt"
    },
    {
      "x": 49,
      "y": 4,
      "z": 25,
      "name": "Rock_Basalt"
    },
    {
      "x": 49,
      "y": 5,
      "z": 25,
      "name": "Rock_Basalt"
    },
    {
      "x": 49,
      "y": 6,
      "z": 25,
      "name": "Rock_Stone"
    },
    {
      "x": 49,
      "y": 7,
      "z": 25,
      "name": "Rock_Basalt"
    },
    {
      "x": 49,
      "y": 8,
      "z": 25,
      "name": "Soil_Gravel"
    },
    {
      "x": 49,
      "y": 9,
      "z": 25,
      "name": "Soil_Gravel"
    },
    {
      "x": 49,
      "y": 10,
      "z": 25,
      "name": "Rock_Basalt_Cobble"
    },
    {
      "x": 49,
      "y": 11,
      "z": 25,
      "name": "Rock_Basalt"
    },
    {
      "x": 49,
      "y": 12,
      "z": 25,
      "name": "Ore_Iron_Basalt"
    },
    {
      "x": 49,
      "y": 13,
      "z": 25,
      "name": "Rock_Basalt"
    },
    {
      "x": 49,
      "y": 14,
      "z": 25,
      "name": "Rock_Basalt"
    },
    {
      "x": 49,
      "y": 15,
      "z": 25,
      "name": "Rock_Basalt"
    },
    {
      "x": 49,
      "y": 16,
      "z": 25,
      "name": "Rock_Basalt"
    },
    {
      "x": 49,
      "y": 17,
      "z": 25,
      "name": "Rock_Basalt"
    },
    {
      "x": 49,
      "y": 18,
      "z": 25,
      "name": "Rock_Basalt"
    },
    {
      "x": 49,
      "y": 19,
      "z": 25,
      "name": "Rock_Basalt"
    },
    {
      "x": 49,
      "y": 20,
      "z": 25,
      "name": "Rock_Basalt_Cobble"
    },
    {
      "x": 49,
      "y": 21,
      "z": 25,
      "name": "Rock_Stone"
    },
    {
      "x": 49,
      "y": -9,
      "z": 26,
      "name": "Rock_Stone"
    },
    {
      "x": 49,
      "y": -8,
      "z": 26,
      "name": "Rock_Stone"
    },
    {
      "x": 49,
      "y": -7,
      "z": 26,
      "name": "Rock_Stone"
    },
    {
      "x": 49,
      "y": -6,
      "z": 26,
      "name": "Rock_Stone"
    },
    {
      "x": 49,
      "y": -5,
      "z": 26,
      "name": "Rock_Stone"
    },
    {
      "x": 49,
      "y": -4,
      "z": 26,
      "name": "Rock_Stone"
    },
    {
      "x": 49,
      "y": -3,
      "z": 26,
      "name": "Rock_Stone"
    },
    {
      "x": 49,
      "y": -2,
      "z": 26,
      "name": "Rock_Stone"
    },
    {
      "x": 49,
      "y": -1,
      "z": 26,
      "name": "Rock_Stone"
    },
    {
      "x": 49,
      "y": 0,
      "z": 26,
      "name": "Rock_Stone"
    },
    {
      "x": 49,
      "y": 1,
      "z": 26,
      "name": "Rock_Stone"
    },
    {
      "x": 49,
      "y": 2,
      "z": 26,
      "name": "Rock_Stone"
    },
    {
      "x": 49,
      "y": 3,
      "z": 26,
      "name": "Rock_Basalt"
    },
    {
      "x": 49,
      "y": 4,
      "z": 26,
      "name": "Rock_Basalt"
    },
    {
      "x": 49,
      "y": 5,
      "z": 26,
      "name": "Rock_Stone"
    },
    {
      "x": 49,
      "y": 6,
      "z": 26,
      "name": "Rock_Basalt_Cobble"
    },
    {
      "x": 49,
      "y": 7,
      "z": 26,
      "name": "Rock_Basalt"
    },
    {
      "x": 49,
      "y": 8,
      "z": 26,
      "name": "Rock_Basalt_Cobble"
    },
    {
      "x": 49,
      "y": 9,
      "z": 26,
      "name": "Soil_Gravel"
    },
    {
      "x": 49,
      "y": 10,
      "z": 26,
      "name": "Rock_Basalt_Cobble"
    },
    {
      "x": 49,
      "y": 11,
      "z": 26,
      "name": "Rock_Stone"
    },
    {
      "x": 49,
      "y": 12,
      "z": 26,
      "name": "Rock_Basalt_Cobble"
    },
    {
      "x": 49,
      "y": 13,
      "z": 26,
      "name": "Rock_Stone"
    },
    {
      "x": 49,
      "y": 14,
      "z": 26,
      "name": "Rock_Stone"
    },
    {
      "x": 49,
      "y": 15,
      "z": 26,
      "name": "Soil_Gravel"
    },
    {
      "x": 49,
      "y": 16,
      "z": 26,
      "name": "Rock_Stone"
    },
    {
      "x": 49,
      "y": 17,
      "z": 26,
      "name": "Soil_Gravel"
    },
    {
      "x": 49,
      "y": 18,
      "z": 26,
      "name": "Soil_Gravel"
    },
    {
      "x": 49,
      "y": 19,
      "z": 26,
      "name": "Rock_Basalt"
    },
    {
      "x": 49,
      "y": 20,
      "z": 26,
      "name": "Rock_Basalt_Cobble"
    },
    {
      "x": 49,
      "y": 21,
      "z": 26,
      "name": "Soil_Gravel"
    },
    {
      "x": 49,
      "y": 22,
      "z": 26,
      "name": "Rock_Stone"
    },
    {
      "x": 49,
      "y": -9,
      "z": 27,
      "name": "Rock_Stone"
    },
    {
      "x": 49,
      "y": -8,
      "z": 27,
      "name": "Rock_Stone"
    },
    {
      "x": 49,
      "y": -7,
      "z": 27,
      "name": "Rock_Stone"
    },
    {
      "x": 49,
      "y": -6,
      "z": 27,
      "name": "Rock_Stone"
    },
    {
      "x": 49,
      "y": -5,
      "z": 27,
      "name": "Rock_Stone"
    },
    {
      "x": 49,
      "y": -4,
      "z": 27,
      "name": "Rock_Stone"
    },
    {
      "x": 49,
      "y": -3,
      "z": 27,
      "name": "Rock_Stone"
    },
    {
      "x": 49,
      "y": -2,
      "z": 27,
      "name": "Rock_Stone"
    },
    {
      "x": 49,
      "y": -1,
      "z": 27,
      "name": "Rock_Stone"
    },
    {
      "x": 49,
      "y": 0,
      "z": 27,
      "name": "Rock_Stone"
    },
    {
      "x": 49,
      "y": 1,
      "z": 27,
      "name": "Rock_Stone"
    },
    {
      "x": 49,
      "y": 2,
      "z": 27,
      "name": "Rock_Stone"
    },
    {
      "x": 49,
      "y": 3,
      "z": 27,
      "name": "Rock_Stone"
    },
    {
      "x": 49,
      "y": 4,
      "z": 27,
      "name": "Soil_Gravel"
    },
    {
      "x": 49,
      "y": 5,
      "z": 27,
      "name": "Rock_Basalt"
    },
    {
      "x": 49,
      "y": 6,
      "z": 27,
      "name": "Ore_Copper_Stone"
    },
    {
      "x": 49,
      "y": 7,
      "z": 27,
      "name": "Ore_Iron_Basalt"
    },
    {
      "x": 49,
      "y": 8,
      "z": 27,
      "name": "Rock_Basalt"
    },
    {
      "x": 49,
      "y": 9,
      "z": 27,
      "name": "Soil_Gravel"
    },
    {
      "x": 49,
      "y": 10,
      "z": 27,
      "name": "Rock_Basalt"
    },
    {
      "x": 49,
      "y": 11,
      "z": 27,
      "name": "Soil_Gravel"
    },
    {
      "x": 49,
      "y": 12,
      "z": 27,
      "name": "Rock_Stone"
    },
    {
      "x": 49,
      "y": 13,
      "z": 27,
      "name": "Soil_Gravel"
    },
    {
      "x": 49,
      "y": 14,
      "z": 27,
      "name": "Rock_Basalt_Cobble"
    },
    {
      "x": 49,
      "y": 15,
      "z": 27,
      "name": "Rock_Basalt"
    },
    {
      "x": 49,
      "y": 16,
      "z": 27,
      "name": "Soil_Gravel"
    },
    {
      "x": 49,
      "y": 17,
      "z": 27,
      "name": "Rock_Basalt"
    },
    {
      "x": 49,
      "y": 18,
      "z": 27,
      "name": "Soil_Gravel"
    },
    {
      "x": 49,
      "y": 19,
      "z": 27,
      "name": "Soil_Gravel"
    },
    {
      "x": 49,
      "y": 20,
      "z": 27,
      "name": "Rock_Basalt"
    },
    {
      "x": 49,
      "y": 21,
      "z": 27,
      "name": "Rock_Stone"
    },
    {
      "x": 49,
      "y": 22,
      "z": 27,
      "name": "Rock_Basalt"
    },
    {
      "x": 49,
      "y": -9,
      "z": 28,
      "name": "Rock_Stone"
    },
    {
      "x": 49,
      "y": -8,
      "z": 28,
      "name": "Rock_Stone"
    },
    {
      "x": 49,
      "y": -7,
      "z": 28,
      "name": "Rock_Stone"
    },
    {
      "x": 49,
      "y": -6,
      "z": 28,
      "name": "Rock_Stone"
    },
    {
      "x": 49,
      "y": -5,
      "z": 28,
      "name": "Rock_Stone"
    },
    {
      "x": 49,
      "y": -4,
      "z": 28,
      "name": "Rock_Stone"
    },
    {
      "x": 49,
      "y": -3,
      "z": 28,
      "name": "Rock_Stone"
    },
    {
      "x": 49,
      "y": -2,
      "z": 28,
      "name": "Rock_Stone"
    },
    {
      "x": 49,
      "y": -1,
      "z": 28,
      "name": "Rock_Stone"
    },
    {
      "x": 49,
      "y": 0,
      "z": 28,
      "name": "Rock_Stone"
    },
    {
      "x": 49,
      "y": 1,
      "z": 28,
      "name": "Rock_Stone"
    },
    {
      "x": 49,
      "y": 2,
      "z": 28,
      "name": "Rock_Stone"
    },
    {
      "x": 49,
      "y": 3,
      "z": 28,
      "name": "Rock_Basalt"
    },
    {
      "x": 49,
      "y": 4,
      "z": 28,
      "name": "Ore_Copper_Stone"
    },
    {
      "x": 49,
      "y": 5,
      "z": 28,
      "name": "Rock_Basalt"
    },
    {
      "x": 49,
      "y": 6,
      "z": 28,
      "name": "Rock_Stone"
    },
    {
      "x": 49,
      "y": 7,
      "z": 28,
      "name": "Rock_Basalt_Cobble"
    },
    {
      "x": 49,
      "y": 8,
      "z": 28,
      "name": "Soil_Gravel"
    },
    {
      "x": 49,
      "y": 9,
      "z": 28,
      "name": "Rock_Stone"
    },
    {
      "x": 49,
      "y": 10,
      "z": 28,
      "name": "Soil_Gravel"
    },
    {
      "x": 49,
      "y": 11,
      "z": 28,
      "name": "Rock_Basalt"
    },
    {
      "x": 49,
      "y": 12,
      "z": 28,
      "name": "Rock_Stone"
    },
    {
      "x": 49,
      "y": 13,
      "z": 28,
      "name": "Rock_Basalt"
    },
    {
      "x": 49,
      "y": 14,
      "z": 28,
      "name": "Rock_Basalt_Cobble"
    },
    {
      "x": 49,
      "y": 15,
      "z": 28,
      "name": "Rock_Basalt"
    },
    {
      "x": 49,
      "y": 16,
      "z": 28,
      "name": "Rock_Basalt_Cobble"
    },
    {
      "x": 49,
      "y": 17,
      "z": 28,
      "name": "Rock_Basalt"
    },
    {
      "x": 49,
      "y": 18,
      "z": 28,
      "name": "Rock_Basalt"
    },
    {
      "x": 49,
      "y": 19,
      "z": 28,
      "name": "Rock_Basalt_Cobble"
    },
    {
      "x": 49,
      "y": 20,
      "z": 28,
      "name": "Rock_Stone"
    },
    {
      "x": 49,
      "y": 21,
      "z": 28,
      "name": "Rock_Basalt_Cobble"
    },
    {
      "x": 49,
      "y": 22,
      "z": 28,
      "name": "Ore_Iron_Basalt"
    },
    {
      "x": 49,
      "y": -9,
      "z": 29,
      "name": "Rock_Stone"
    },
    {
      "x": 49,
      "y": -8,
      "z": 29,
      "name": "Rock_Stone"
    },
    {
      "x": 49,
      "y": -7,
      "z": 29,
      "name": "Rock_Stone"
    },
    {
      "x": 49,
      "y": -6,
      "z": 29,
      "name": "Rock_Stone"
    },
    {
      "x": 49,
      "y": -5,
      "z": 29,
      "name": "Rock_Stone"
    },
    {
      "x": 49,
      "y": -4,
      "z": 29,
      "name": "Rock_Stone"
    },
    {
      "x": 49,
      "y": -3,
      "z": 29,
      "name": "Rock_Stone"
    },
    {
      "x": 49,
      "y": -2,
      "z": 29,
      "name": "Rock_Stone"
    },
    {
      "x": 49,
      "y": -1,
      "z": 29,
      "name": "Rock_Stone"
    },
    {
      "x": 49,
      "y": 0,
      "z": 29,
      "name": "Rock_Stone"
    },
    {
      "x": 49,
      "y": 1,
      "z": 29,
      "name": "Rock_Stone"
    },
    {
      "x": 49,
      "y": 2,
      "z": 29,
      "name": "Rock_Stone"
    },
    {
      "x": 49,
      "y": 3,
      "z": 29,
      "name": "Rock_Stone"
    },
    {
      "x": 49,
      "y": 4,
      "z": 29,
      "name": "Rock_Basalt_Cobble"
    },
    {
      "x": 49,
      "y": 5,
      "z": 29,
      "name": "Soil_Gravel"
    },
    {
      "x": 49,
      "y": 6,
      "z": 29,
      "name": "Rock_Basalt"
    },
    {
      "x": 49,
      "y": 7,
      "z": 29,
      "name": "Soil_Gravel"
    },
    {
      "x": 49,
      "y": 8,
      "z": 29,
      "name": "Rock_Stone"
    },
    {
      "x": 49,
      "y": 9,
      "z": 29,
      "name": "Rock_Basalt"
    },
    {
      "x": 49,
      "y": 10,
      "z": 29,
      "name": "Rock_Basalt_Cobble"
    },
    {
      "x": 49,
      "y": 11,
      "z": 29,
      "name": "Rock_Stone"
    },
    {
      "x": 49,
      "y": 12,
      "z": 29,
      "name": "Rock_Basalt_Cobble"
    },
    {
      "x": 49,
      "y": 13,
      "z": 29,
      "name": "Rock_Basalt_Cobble"
    },
    {
      "x": 49,
      "y": 14,
      "z": 29,
      "name": "Rock_Basalt_Cobble"
    },
    {
      "x": 49,
      "y": 15,
      "z": 29,
      "name": "Rock_Stone"
    },
    {
      "x": 49,
      "y": 16,
      "z": 29,
      "name": "Rock_Stone"
    },
    {
      "x": 49,
      "y": 17,
      "z": 29,
      "name": "Rock_Basalt"
    },
    {
      "x": 49,
      "y": 18,
      "z": 29,
      "name": "Rock_Basalt_Cobble"
    },
    {
      "x": 49,
      "y": 19,
      "z": 29,
      "name": "Rock_Stone"
    },
    {
      "x": 49,
      "y": 20,
      "z": 29,
      "name": "Rock_Basalt"
    },
    {
      "x": 49,
      "y": 21,
      "z": 29,
      "name": "Rock_Basalt"
    },
    {
      "x": 49,
      "y": 22,
      "z": 29,
      "name": "Rock_Basalt_Cobble"
    },
    {
      "x": 49,
      "y": -9,
      "z": 30,
      "name": "Rock_Stone"
    },
    {
      "x": 49,
      "y": -8,
      "z": 30,
      "name": "Rock_Stone"
    },
    {
      "x": 49,
      "y": -7,
      "z": 30,
      "name": "Rock_Stone"
    },
    {
      "x": 49,
      "y": -6,
      "z": 30,
      "name": "Rock_Stone"
    },
    {
      "x": 49,
      "y": -5,
      "z": 30,
      "name": "Rock_Stone"
    },
    {
      "x": 49,
      "y": -4,
      "z": 30,
      "name": "Rock_Stone"
    },
    {
      "x": 49,
      "y": -3,
      "z": 30,
      "name": "Rock_Stone"
    },
    {
      "x": 49,
      "y": -2,
      "z": 30,
      "name": "Rock_Stone"
    },
    {
      "x": 49,
      "y": -1,
      "z": 30,
      "name": "Rock_Stone"
    },
    {
      "x": 49,
      "y": 0,
      "z": 30,
      "name": "Rock_Stone"
    },
    {
      "x": 49,
      "y": 1,
      "z": 30,
      "name": "Rock_Stone"
    },
    {
      "x": 49,
      "y": 2,
      "z": 30,
      "name": "Rock_Stone"
    },
    {
      "x": 49,
      "y": 3,
      "z": 30,
      "name": "Rock_Basalt"
    },
    {
      "x": 49,
      "y": 4,
      "z": 30,
      "name": "Ore_Copper_Stone"
    },
    {
      "x": 49,
      "y": 5,
      "z": 30,
      "name": "Rock_Basalt_Cobble"
    },
    {
      "x": 49,
      "y": 6,
      "z": 30,
      "name": "Soil_Gravel"
    },
    {
      "x": 49,
      "y": 7,
      "z": 30,
      "name": "Rock_Basalt_Cobble"
    },
    {
      "x": 49,
      "y": 8,
      "z": 30,
      "name": "Soil_Gravel"
    },
    {
      "x": 49,
      "y": 9,
      "z": 30,
      "name": "Rock_Basalt"
    },
    {
      "x": 49,
      "y": 10,
      "z": 30,
      "name": "Rock_Basalt_Cobble"
    },
    {
      "x": 49,
      "y": 11,
      "z": 30,
      "name": "Rock_Basalt"
    },
    {
      "x": 49,
      "y": 12,
      "z": 30,
      "name": "Rock_Basalt"
    },
    {
      "x": 49,
      "y": 13,
      "z": 30,
      "name": "Soil_Gravel"
    },
    {
      "x": 49,
      "y": 14,
      "z": 30,
      "name": "Rock_Stone"
    },
    {
      "x": 49,
      "y": 15,
      "z": 30,
      "name": "Rock_Basalt_Cobble"
    },
    {
      "x": 49,
      "y": 16,
      "z": 30,
      "name": "Rock_Basalt_Cobble"
    },
    {
      "x": 49,
      "y": 17,
      "z": 30,
      "name": "Rock_Stone"
    },
    {
      "x": 49,
      "y": 18,
      "z": 30,
      "name": "Rock_Stone"
    },
    {
      "x": 49,
      "y": 19,
      "z": 30,
      "name": "Rock_Basalt"
    },
    {
      "x": 49,
      "y": 20,
      "z": 30,
      "name": "Ore_Copper_Stone"
    },
    {
      "x": 49,
      "y": 21,
      "z": 30,
      "name": "Soil_Gravel"
    },
    {
      "x": 49,
      "y": 22,
      "z": 30,
      "name": "Rock_Basalt"
    },
    {
      "x": 49,
      "y": -9,
      "z": 31,
      "name": "Rock_Stone"
    },
    {
      "x": 49,
      "y": -8,
      "z": 31,
      "name": "Rock_Stone"
    },
    {
      "x": 49,
      "y": -7,
      "z": 31,
      "name": "Rock_Stone"
    },
    {
      "x": 49,
      "y": -6,
      "z": 31,
      "name": "Rock_Stone"
    },
    {
      "x": 49,
      "y": -5,
      "z": 31,
      "name": "Rock_Stone"
    },
    {
      "x": 49,
      "y": -4,
      "z": 31,
      "name": "Rock_Stone"
    },
    {
      "x": 49,
      "y": -3,
      "z": 31,
      "name": "Rock_Stone"
    },
    {
      "x": 49,
      "y": -2,
      "z": 31,
      "name": "Rock_Stone"
    },
    {
      "x": 49,
      "y": -1,
      "z": 31,
      "name": "Rock_Stone"
    },
    {
      "x": 49,
      "y": 0,
      "z": 31,
      "name": "Rock_Stone"
    },
    {
      "x": 49,
      "y": 1,
      "z": 31,
      "name": "Rock_Stone"
    },
    {
      "x": 49,
      "y": 2,
      "z": 31,
      "name": "Rock_Stone"
    },
    {
      "x": 49,
      "y": 3,
      "z": 31,
      "name": "Rock_Basalt"
    },
    {
      "x": 49,
      "y": 4,
      "z": 31,
      "name": "Rock_Basalt_Cobble"
    },
    {
      "x": 49,
      "y": 5,
      "z": 31,
      "name": "Rock_Basalt_Cobble"
    },
    {
      "x": 49,
      "y": 6,
      "z": 31,
      "name": "Soil_Gravel"
    },
    {
      "x": 49,
      "y": 7,
      "z": 31,
      "name": "Rock_Stone"
    },
    {
      "x": 49,
      "y": 8,
      "z": 31,
      "name": "Rock_Basalt_Cobble"
    },
    {
      "x": 49,
      "y": 9,
      "z": 31,
      "name": "Soil_Gravel"
    },
    {
      "x": 49,
      "y": 10,
      "z": 31,
      "name": "Rock_Basalt"
    },
    {
      "x": 49,
      "y": 11,
      "z": 31,
      "name": "Rock_Stone"
    },
    {
      "x": 49,
      "y": 12,
      "z": 31,
      "name": "Rock_Stone"
    },
    {
      "x": 49,
      "y": 13,
      "z": 31,
      "name": "Rock_Basalt"
    },
    {
      "x": 49,
      "y": 14,
      "z": 31,
      "name": "Rock_Basalt_Cobble"
    },
    {
      "x": 49,
      "y": 15,
      "z": 31,
      "name": "Rock_Basalt"
    },
    {
      "x": 49,
      "y": 16,
      "z": 31,
      "name": "Soil_Gravel"
    },
    {
      "x": 49,
      "y": 17,
      "z": 31,
      "name": "Rock_Stone"
    },
    {
      "x": 49,
      "y": 18,
      "z": 31,
      "name": "Rock_Basalt"
    },
    {
      "x": 49,
      "y": 19,
      "z": 31,
      "name": "Rock_Stone"
    },
    {
      "x": 49,
      "y": 20,
      "z": 31,
      "name": "Soil_Gravel"
    },
    {
      "x": 49,
      "y": 21,
      "z": 31,
      "name": "Rock_Stone"
    },
    {
      "x": 49,
      "y": -9,
      "z": 32,
      "name": "Rock_Stone"
    },
    {
      "x": 49,
      "y": -8,
      "z": 32,
      "name": "Rock_Stone"
    },
    {
      "x": 49,
      "y": -7,
      "z": 32,
      "name": "Rock_Stone"
    },
    {
      "x": 49,
      "y": -6,
      "z": 32,
      "name": "Rock_Stone"
    },
    {
      "x": 49,
      "y": -5,
      "z": 32,
      "name": "Rock_Stone"
    },
    {
      "x": 49,
      "y": -4,
      "z": 32,
      "name": "Rock_Stone"
    },
    {
      "x": 49,
      "y": -3,
      "z": 32,
      "name": "Rock_Stone"
    },
    {
      "x": 49,
      "y": -2,
      "z": 32,
      "name": "Rock_Stone"
    },
    {
      "x": 49,
      "y": -1,
      "z": 32,
      "name": "Rock_Stone"
    },
    {
      "x": 49,
      "y": 0,
      "z": 32,
      "name": "Rock_Stone"
    },
    {
      "x": 49,
      "y": 1,
      "z": 32,
      "name": "Rock_Stone"
    },
    {
      "x": 49,
      "y": 2,
      "z": 32,
      "name": "Rock_Stone"
    },
    {
      "x": 49,
      "y": 3,
      "z": 32,
      "name": "Rock_Basalt"
    },
    {
      "x": 49,
      "y": 4,
      "z": 32,
      "name": "Soil_Gravel"
    },
    {
      "x": 49,
      "y": 5,
      "z": 32,
      "name": "Rock_Basalt"
    },
    {
      "x": 49,
      "y": 6,
      "z": 32,
      "name": "Rock_Basalt"
    },
    {
      "x": 49,
      "y": 7,
      "z": 32,
      "name": "Rock_Stone"
    },
    {
      "x": 49,
      "y": 8,
      "z": 32,
      "name": "Soil_Gravel"
    },
    {
      "x": 49,
      "y": 9,
      "z": 32,
      "name": "Rock_Stone"
    },
    {
      "x": 49,
      "y": 10,
      "z": 32,
      "name": "Rock_Basalt_Cobble"
    },
    {
      "x": 49,
      "y": 11,
      "z": 32,
      "name": "Rock_Stone"
    },
    {
      "x": 49,
      "y": 12,
      "z": 32,
      "name": "Ore_Copper_Stone"
    },
    {
      "x": 49,
      "y": 13,
      "z": 32,
      "name": "Rock_Stone"
    },
    {
      "x": 49,
      "y": 14,
      "z": 32,
      "name": "Soil_Gravel"
    },
    {
      "x": 49,
      "y": 15,
      "z": 32,
      "name": "Soil_Gravel"
    },
    {
      "x": 49,
      "y": 16,
      "z": 32,
      "name": "Rock_Basalt_Cobble"
    },
    {
      "x": 49,
      "y": 17,
      "z": 32,
      "name": "Rock_Stone"
    },
    {
      "x": 49,
      "y": 18,
      "z": 32,
      "name": "Rock_Basalt_Cobble"
    },
    {
      "x": 49,
      "y": 19,
      "z": 32,
      "name": "Rock_Basalt"
    },
    {
      "x": 49,
      "y": 20,
      "z": 32,
      "name": "Soil_Gravel"
    },
    {
      "x": 49,
      "y": 21,
      "z": 32,
      "name": "Rock_Basalt"
    },
    {
      "x": 49,
      "y": -9,
      "z": 33,
      "name": "Rock_Stone"
    },
    {
      "x": 49,
      "y": -8,
      "z": 33,
      "name": "Rock_Stone"
    },
    {
      "x": 49,
      "y": -7,
      "z": 33,
      "name": "Rock_Stone"
    },
    {
      "x": 49,
      "y": -6,
      "z": 33,
      "name": "Rock_Stone"
    },
    {
      "x": 49,
      "y": -5,
      "z": 33,
      "name": "Rock_Stone"
    },
    {
      "x": 49,
      "y": -4,
      "z": 33,
      "name": "Rock_Stone"
    },
    {
      "x": 49,
      "y": -3,
      "z": 33,
      "name": "Rock_Stone"
    },
    {
      "x": 49,
      "y": -2,
      "z": 33,
      "name": "Rock_Stone"
    },
    {
      "x": 49,
      "y": -1,
      "z": 33,
      "name": "Rock_Stone"
    },
    {
      "x": 49,
      "y": 0,
      "z": 33,
      "name": "Rock_Stone"
    },
    {
      "x": 49,
      "y": 1,
      "z": 33,
      "name": "Rock_Stone"
    },
    {
      "x": 49,
      "y": 2,
      "z": 33,
      "name": "Rock_Stone"
    },
    {
      "x": 49,
      "y": 3,
      "z": 33,
      "name": "Rock_Basalt_Cobble"
    },
    {
      "x": 49,
      "y": 4,
      "z": 33,
      "name": "Rock_Basalt"
    },
    {
      "x": 49,
      "y": 5,
      "z": 33,
      "name": "Rock_Stone"
    },
    {
      "x": 49,
      "y": 6,
      "z": 33,
      "name": "Soil_Gravel"
    },
    {
      "x": 49,
      "y": 7,
      "z": 33,
      "name": "Rock_Basalt"
    },
    {
      "x": 49,
      "y": 8,
      "z": 33,
      "name": "Soil_Gravel"
    },
    {
      "x": 49,
      "y": 9,
      "z": 33,
      "name": "Rock_Basalt"
    },
    {
      "x": 49,
      "y": 10,
      "z": 33,
      "name": "Soil_Gravel"
    },
    {
      "x": 49,
      "y": 11,
      "z": 33,
      "name": "Rock_Basalt"
    },
    {
      "x": 49,
      "y": 12,
      "z": 33,
      "name": "Rock_Basalt"
    },
    {
      "x": 49,
      "y": 13,
      "z": 33,
      "name": "Rock_Basalt_Cobble"
    },
    {
      "x": 49,
      "y": 14,
      "z": 33,
      "name": "Rock_Stone"
    },
    {
      "x": 49,
      "y": 15,
      "z": 33,
      "name": "Rock_Basalt_Cobble"
    },
    {
      "x": 49,
      "y": 16,
      "z": 33,
      "name": "Rock_Basalt"
    },
    {
      "x": 49,
      "y": 17,
      "z": 33,
      "name": "Rock_Stone"
    },
    {
      "x": 49,
      "y": 18,
      "z": 33,
      "name": "Rock_Stone"
    },
    {
      "x": 49,
      "y": 19,
      "z": 33,
      "name": "Soil_Gravel"
    },
    {
      "x": 49,
      "y": 20,
      "z": 33,
      "name": "Rock_Stone"
    },
    {
      "x": 49,
      "y": -9,
      "z": 34,
      "name": "Rock_Stone"
    },
    {
      "x": 49,
      "y": -8,
      "z": 34,
      "name": "Rock_Stone"
    },
    {
      "x": 49,
      "y": -7,
      "z": 34,
      "name": "Rock_Stone"
    },
    {
      "x": 49,
      "y": -6,
      "z": 34,
      "name": "Rock_Stone"
    },
    {
      "x": 49,
      "y": -5,
      "z": 34,
      "name": "Rock_Stone"
    },
    {
      "x": 49,
      "y": -4,
      "z": 34,
      "name": "Rock_Stone"
    },
    {
      "x": 49,
      "y": -3,
      "z": 34,
      "name": "Rock_Stone"
    },
    {
      "x": 49,
      "y": -2,
      "z": 34,
      "name": "Rock_Stone"
    },
    {
      "x": 49,
      "y": -1,
      "z": 34,
      "name": "Rock_Stone"
    },
    {
      "x": 49,
      "y": 0,
      "z": 34,
      "name": "Rock_Stone"
    },
    {
      "x": 49,
      "y": 1,
      "z": 34,
      "name": "Rock_Stone"
    },
    {
      "x": 49,
      "y": 2,
      "z": 34,
      "name": "Rock_Stone"
    },
    {
      "x": 49,
      "y": 3,
      "z": 34,
      "name": "Rock_Basalt"
    },
    {
      "x": 49,
      "y": 4,
      "z": 34,
      "name": "Rock_Stone"
    },
    {
      "x": 49,
      "y": 5,
      "z": 34,
      "name": "Soil_Gravel"
    },
    {
      "x": 49,
      "y": 6,
      "z": 34,
      "name": "Soil_Gravel"
    },
    {
      "x": 49,
      "y": 7,
      "z": 34,
      "name": "Rock_Basalt_Cobble"
    },
    {
      "x": 49,
      "y": 8,
      "z": 34,
      "name": "Soil_Gravel"
    },
    {
      "x": 49,
      "y": 9,
      "z": 34,
      "name": "Rock_Basalt"
    },
    {
      "x": 49,
      "y": 10,
      "z": 34,
      "name": "Rock_Basalt_Cobble"
    },
    {
      "x": 49,
      "y": 11,
      "z": 34,
      "name": "Rock_Basalt"
    },
    {
      "x": 49,
      "y": 12,
      "z": 34,
      "name": "Rock_Stone"
    },
    {
      "x": 49,
      "y": 13,
      "z": 34,
      "name": "Rock_Basalt_Cobble"
    },
    {
      "x": 49,
      "y": 14,
      "z": 34,
      "name": "Rock_Basalt_Cobble"
    },
    {
      "x": 49,
      "y": 15,
      "z": 34,
      "name": "Rock_Basalt"
    },
    {
      "x": 49,
      "y": 16,
      "z": 34,
      "name": "Rock_Basalt"
    },
    {
      "x": 49,
      "y": 17,
      "z": 34,
      "name": "Rock_Basalt"
    },
    {
      "x": 49,
      "y": 18,
      "z": 34,
      "name": "Rock_Stone"
    },
    {
      "x": 49,
      "y": 19,
      "z": 34,
      "name": "Rock_Stone"
    },
    {
      "x": 49,
      "y": 20,
      "z": 34,
      "name": "Ore_Copper_Stone"
    },
    {
      "x": 49,
      "y": -9,
      "z": 35,
      "name": "Rock_Stone"
    },
    {
      "x": 49,
      "y": -8,
      "z": 35,
      "name": "Rock_Stone"
    },
    {
      "x": 49,
      "y": -7,
      "z": 35,
      "name": "Rock_Stone"
    },
    {
      "x": 49,
      "y": -6,
      "z": 35,
      "name": "Rock_Stone"
    },
    {
      "x": 49,
      "y": -5,
      "z": 35,
      "name": "Rock_Stone"
    },
    {
      "x": 49,
      "y": -4,
      "z": 35,
      "name": "Rock_Stone"
    },
    {
      "x": 49,
      "y": -3,
      "z": 35,
      "name": "Rock_Stone"
    },
    {
      "x": 49,
      "y": -2,
      "z": 35,
      "name": "Rock_Stone"
    },
    {
      "x": 49,
      "y": -1,
      "z": 35,
      "name": "Rock_Stone"
    },
    {
      "x": 49,
      "y": 0,
      "z": 35,
      "name": "Rock_Stone"
    },
    {
      "x": 49,
      "y": 1,
      "z": 35,
      "name": "Rock_Stone"
    },
    {
      "x": 49,
      "y": 2,
      "z": 35,
      "name": "Rock_Stone"
    },
    {
      "x": 49,
      "y": 3,
      "z": 35,
      "name": "Soil_Gravel"
    },
    {
      "x": 49,
      "y": 4,
      "z": 35,
      "name": "Soil_Gravel"
    },
    {
      "x": 49,
      "y": 5,
      "z": 35,
      "name": "Rock_Basalt"
    },
    {
      "x": 49,
      "y": 6,
      "z": 35,
      "name": "Rock_Stone"
    },
    {
      "x": 49,
      "y": 7,
      "z": 35,
      "name": "Rock_Stone"
    },
    {
      "x": 49,
      "y": 8,
      "z": 35,
      "name": "Rock_Basalt"
    },
    {
      "x": 49,
      "y": 9,
      "z": 35,
      "name": "Rock_Basalt"
    },
    {
      "x": 49,
      "y": 10,
      "z": 35,
      "name": "Ore_Copper_Stone"
    },
    {
      "x": 49,
      "y": 11,
      "z": 35,
      "name": "Soil_Gravel"
    },
    {
      "x": 49,
      "y": 12,
      "z": 35,
      "name": "Rock_Basalt_Cobble"
    },
    {
      "x": 49,
      "y": 13,
      "z": 35,
      "name": "Rock_Stone"
    },
    {
      "x": 49,
      "y": 14,
      "z": 35,
      "name": "Rock_Basalt"
    },
    {
      "x": 49,
      "y": 15,
      "z": 35,
      "name": "Rock_Basalt"
    },
    {
      "x": 49,
      "y": 16,
      "z": 35,
      "name": "Rock_Basalt"
    },
    {
      "x": 49,
      "y": 17,
      "z": 35,
      "name": "Rock_Basalt"
    },
    {
      "x": 49,
      "y": 18,
      "z": 35,
      "name": "Rock_Stone"
    },
    {
      "x": 49,
      "y": 19,
      "z": 35,
      "name": "Rock_Stone"
    },
    {
      "x": 49,
      "y": 20,
      "z": 35,
      "name": "Rock_Basalt"
    },
    {
      "x": 49,
      "y": -9,
      "z": 36,
      "name": "Rock_Stone"
    },
    {
      "x": 49,
      "y": -8,
      "z": 36,
      "name": "Rock_Stone"
    },
    {
      "x": 49,
      "y": -7,
      "z": 36,
      "name": "Soil_Gravel"
    },
    {
      "x": 49,
      "y": -6,
      "z": 36,
      "name": "Rock_Stone"
    },
    {
      "x": 49,
      "y": -5,
      "z": 36,
      "name": "Rock_Stone"
    },
    {
      "x": 49,
      "y": -4,
      "z": 36,
      "name": "Rock_Stone"
    },
    {
      "x": 49,
      "y": -3,
      "z": 36,
      "name": "Rock_Stone"
    },
    {
      "x": 49,
      "y": -2,
      "z": 36,
      "name": "Rock_Stone"
    },
    {
      "x": 49,
      "y": -1,
      "z": 36,
      "name": "Rock_Stone"
    },
    {
      "x": 49,
      "y": 0,
      "z": 36,
      "name": "Rock_Stone"
    },
    {
      "x": 49,
      "y": 1,
      "z": 36,
      "name": "Rock_Basalt"
    },
    {
      "x": 49,
      "y": 2,
      "z": 36,
      "name": "Rock_Basalt"
    },
    {
      "x": 49,
      "y": 3,
      "z": 36,
      "name": "Soil_Gravel"
    },
    {
      "x": 49,
      "y": 4,
      "z": 36,
      "name": "Rock_Stone"
    },
    {
      "x": 49,
      "y": 5,
      "z": 36,
      "name": "Rock_Basalt"
    },
    {
      "x": 49,
      "y": 6,
      "z": 36,
      "name": "Rock_Basalt_Cobble"
    },
    {
      "x": 49,
      "y": 7,
      "z": 36,
      "name": "Rock_Basalt_Cobble"
    },
    {
      "x": 49,
      "y": 8,
      "z": 36,
      "name": "Rock_Basalt_Cobble"
    },
    {
      "x": 49,
      "y": 9,
      "z": 36,
      "name": "Rock_Stone"
    },
    {
      "x": 49,
      "y": 10,
      "z": 36,
      "name": "Rock_Basalt_Cobble"
    },
    {
      "x": 49,
      "y": 11,
      "z": 36,
      "name": "Rock_Stone"
    },
    {
      "x": 49,
      "y": 12,
      "z": 36,
      "name": "Rock_Stone"
    },
    {
      "x": 49,
      "y": 13,
      "z": 36,
      "name": "Rock_Stone"
    },
    {
      "x": 49,
      "y": 14,
      "z": 36,
      "name": "Rock_Basalt"
    },
    {
      "x": 49,
      "y": 15,
      "z": 36,
      "name": "Rock_Basalt"
    },
    {
      "x": 49,
      "y": 16,
      "z": 36,
      "name": "Rock_Basalt"
    },
    {
      "x": 49,
      "y": 17,
      "z": 36,
      "name": "Rock_Basalt"
    },
    {
      "x": 49,
      "y": 18,
      "z": 36,
      "name": "Rock_Basalt_Cobble"
    },
    {
      "x": 49,
      "y": 19,
      "z": 36,
      "name": "Rock_Basalt_Cobble"
    },
    {
      "x": 49,
      "y": -9,
      "z": 37,
      "name": "Soil_Gravel"
    },
    {
      "x": 49,
      "y": -8,
      "z": 37,
      "name": "Rock_Basalt"
    },
    {
      "x": 49,
      "y": -7,
      "z": 37,
      "name": "Rock_Stone"
    },
    {
      "x": 49,
      "y": -6,
      "z": 37,
      "name": "Soil_Gravel"
    },
    {
      "x": 49,
      "y": -5,
      "z": 37,
      "name": "Soil_Gravel"
    },
    {
      "x": 49,
      "y": -4,
      "z": 37,
      "name": "Rock_Basalt"
    },
    {
      "x": 49,
      "y": -3,
      "z": 37,
      "name": "Soil_Gravel"
    },
    {
      "x": 49,
      "y": -2,
      "z": 37,
      "name": "Soil_Gravel"
    },
    {
      "x": 49,
      "y": -1,
      "z": 37,
      "name": "Rock_Basalt"
    },
    {
      "x": 49,
      "y": 0,
      "z": 37,
      "name": "Rock_Basalt_Cobble"
    },
    {
      "x": 49,
      "y": 1,
      "z": 37,
      "name": "Rock_Stone"
    },
    {
      "x": 49,
      "y": 2,
      "z": 37,
      "name": "Rock_Basalt"
    },
    {
      "x": 49,
      "y": 3,
      "z": 37,
      "name": "Rock_Basalt"
    },
    {
      "x": 49,
      "y": 4,
      "z": 37,
      "name": "Rock_Basalt"
    },
    {
      "x": 49,
      "y": 5,
      "z": 37,
      "name": "Rock_Basalt_Cobble"
    },
    {
      "x": 49,
      "y": 6,
      "z": 37,
      "name": "Soil_Gravel"
    },
    {
      "x": 49,
      "y": 7,
      "z": 37,
      "name": "Soil_Gravel"
    },
    {
      "x": 49,
      "y": 8,
      "z": 37,
      "name": "Rock_Stone"
    },
    {
      "x": 49,
      "y": 9,
      "z": 37,
      "name": "Rock_Stone"
    },
    {
      "x": 49,
      "y": 10,
      "z": 37,
      "name": "Rock_Basalt_Cobble"
    },
    {
      "x": 49,
      "y": 11,
      "z": 37,
      "name": "Rock_Basalt_Cobble"
    },
    {
      "x": 49,
      "y": 12,
      "z": 37,
      "name": "Rock_Basalt_Cobble"
    },
    {
      "x": 49,
      "y": 13,
      "z": 37,
      "name": "Rock_Stone"
    },
    {
      "x": 49,
      "y": 14,
      "z": 37,
      "name": "Rock_Stone"
    },
    {
      "x": 49,
      "y": 15,
      "z": 37,
      "name": "Rock_Basalt"
    },
    {
      "x": 49,
      "y": 16,
      "z": 37,
      "name": "Rock_Basalt"
    },
    {
      "x": 49,
      "y": 17,
      "z": 37,
      "name": "Rock_Basalt"
    },
    {
      "x": 49,
      "y": 18,
      "z": 37,
      "name": "Rock_Stone"
    },
    {
      "x": 50,
      "y": -9,
      "z": 24,
      "name": "Rock_Stone"
    },
    {
      "x": 50,
      "y": -8,
      "z": 24,
      "name": "Rock_Stone"
    },
    {
      "x": 50,
      "y": -7,
      "z": 24,
      "name": "Rock_Stone"
    },
    {
      "x": 50,
      "y": -6,
      "z": 24,
      "name": "Rock_Stone"
    },
    {
      "x": 50,
      "y": -5,
      "z": 24,
      "name": "Rock_Stone"
    },
    {
      "x": 50,
      "y": -4,
      "z": 24,
      "name": "Rock_Stone"
    },
    {
      "x": 50,
      "y": -3,
      "z": 24,
      "name": "Rock_Stone"
    },
    {
      "x": 50,
      "y": -2,
      "z": 24,
      "name": "Rock_Stone"
    },
    {
      "x": 50,
      "y": -1,
      "z": 24,
      "name": "Rock_Stone"
    },
    {
      "x": 50,
      "y": 0,
      "z": 24,
      "name": "Rock_Stone"
    },
    {
      "x": 50,
      "y": 1,
      "z": 24,
      "name": "Rock_Stone"
    },
    {
      "x": 50,
      "y": 2,
      "z": 24,
      "name": "Rock_Stone"
    },
    {
      "x": 50,
      "y": 3,
      "z": 24,
      "name": "Rock_Basalt_Cobble"
    },
    {
      "x": 50,
      "y": 4,
      "z": 24,
      "name": "Rock_Basalt"
    },
    {
      "x": 50,
      "y": 5,
      "z": 24,
      "name": "Rock_Basalt"
    },
    {
      "x": 50,
      "y": 6,
      "z": 24,
      "name": "Rock_Basalt"
    },
    {
      "x": 50,
      "y": 7,
      "z": 24,
      "name": "Rock_Basalt"
    },
    {
      "x": 50,
      "y": 8,
      "z": 24,
      "name": "Rock_Basalt_Cobble"
    },
    {
      "x": 50,
      "y": 9,
      "z": 24,
      "name": "Rock_Stone"
    },
    {
      "x": 50,
      "y": 10,
      "z": 24,
      "name": "Rock_Basalt_Cobble"
    },
    {
      "x": 50,
      "y": 11,
      "z": 24,
      "name": "Rock_Basalt"
    },
    {
      "x": 50,
      "y": 12,
      "z": 24,
      "name": "Ore_Iron_Basalt_Cracked"
    },
    {
      "x": 50,
      "y": 13,
      "z": 24,
      "name": "Ore_Iron_Basalt_Cracked"
    },
    {
      "x": 50,
      "y": 14,
      "z": 24,
      "name": "Ore_Iron_Basalt_Cracked"
    },
    {
      "x": 50,
      "y": 15,
      "z": 24,
      "name": "Rock_Basalt"
    },
    {
      "x": 50,
      "y": 16,
      "z": 24,
      "name": "Rock_Basalt"
    },
    {
      "x": 50,
      "y": 17,
      "z": 24,
      "name": "Rock_Basalt"
    },
    {
      "x": 50,
      "y": 18,
      "z": 24,
      "name": "Rock_Stone"
    },
    {
      "x": 50,
      "y": 19,
      "z": 24,
      "name": "Rock_Basalt"
    },
    {
      "x": 50,
      "y": 20,
      "z": 24,
      "name": "Rock_Basalt"
    },
    {
      "x": 50,
      "y": 21,
      "z": 24,
      "name": "Rock_Basalt"
    },
    {
      "x": 50,
      "y": -9,
      "z": 25,
      "name": "Rock_Stone"
    },
    {
      "x": 50,
      "y": -8,
      "z": 25,
      "name": "Rock_Stone"
    },
    {
      "x": 50,
      "y": -7,
      "z": 25,
      "name": "Rock_Stone"
    },
    {
      "x": 50,
      "y": -6,
      "z": 25,
      "name": "Rock_Stone"
    },
    {
      "x": 50,
      "y": -5,
      "z": 25,
      "name": "Rock_Stone"
    },
    {
      "x": 50,
      "y": -4,
      "z": 25,
      "name": "Rock_Stone"
    },
    {
      "x": 50,
      "y": -3,
      "z": 25,
      "name": "Rock_Stone"
    },
    {
      "x": 50,
      "y": -2,
      "z": 25,
      "name": "Rock_Stone"
    },
    {
      "x": 50,
      "y": -1,
      "z": 25,
      "name": "Rock_Stone"
    },
    {
      "x": 50,
      "y": 0,
      "z": 25,
      "name": "Ore_Iron_Stone"
    },
    {
      "x": 50,
      "y": 1,
      "z": 25,
      "name": "Rock_Stone"
    },
    {
      "x": 50,
      "y": 2,
      "z": 25,
      "name": "Rock_Stone"
    },
    {
      "x": 50,
      "y": 3,
      "z": 25,
      "name": "Rock_Basalt_Cobble"
    },
    {
      "x": 50,
      "y": 4,
      "z": 25,
      "name": "Rock_Basalt"
    },
    {
      "x": 50,
      "y": 5,
      "z": 25,
      "name": "Rock_Basalt"
    },
    {
      "x": 50,
      "y": 6,
      "z": 25,
      "name": "Rock_Basalt_Cobble"
    },
    {
      "x": 50,
      "y": 7,
      "z": 25,
      "name": "Rock_Basalt"
    },
    {
      "x": 50,
      "y": 8,
      "z": 25,
      "name": "Ore_Iron_Basalt"
    },
    {
      "x": 50,
      "y": 9,
      "z": 25,
      "name": "Soil_Gravel"
    },
    {
      "x": 50,
      "y": 10,
      "z": 25,
      "name": "Soil_Gravel"
    },
    {
      "x": 50,
      "y": 11,
      "z": 25,
      "name": "Rock_Basalt_Cobble"
    },
    {
      "x": 50,
      "y": 12,
      "z": 25,
      "name": "Rock_Basalt_Cobble"
    },
    {
      "x": 50,
      "y": 13,
      "z": 25,
      "name": "Rock_Basalt"
    },
    {
      "x": 50,
      "y": 14,
      "z": 25,
      "name": "Rock_Basalt"
    },
    {
      "x": 50,
      "y": 15,
      "z": 25,
      "name": "Rock_Basalt"
    },
    {
      "x": 50,
      "y": 16,
      "z": 25,
      "name": "Rock_Basalt_Cobble"
    },
    {
      "x": 50,
      "y": 17,
      "z": 25,
      "name": "Rock_Basalt_Cobble"
    },
    {
      "x": 50,
      "y": 18,
      "z": 25,
      "name": "Rock_Basalt_Cobble"
    },
    {
      "x": 50,
      "y": 19,
      "z": 25,
      "name": "Rock_Basalt"
    },
    {
      "x": 50,
      "y": 20,
      "z": 25,
      "name": "Rock_Stone"
    },
    {
      "x": 50,
      "y": 21,
      "z": 25,
      "name": "Rock_Basalt"
    },
    {
      "x": 50,
      "y": -9,
      "z": 26,
      "name": "Rock_Stone"
    },
    {
      "x": 50,
      "y": -8,
      "z": 26,
      "name": "Rock_Stone"
    },
    {
      "x": 50,
      "y": -7,
      "z": 26,
      "name": "Rock_Stone"
    },
    {
      "x": 50,
      "y": -6,
      "z": 26,
      "name": "Rock_Stone"
    },
    {
      "x": 50,
      "y": -5,
      "z": 26,
      "name": "Rock_Stone"
    },
    {
      "x": 50,
      "y": -4,
      "z": 26,
      "name": "Rock_Stone"
    },
    {
      "x": 50,
      "y": -3,
      "z": 26,
      "name": "Rock_Stone"
    },
    {
      "x": 50,
      "y": -2,
      "z": 26,
      "name": "Rock_Stone"
    },
    {
      "x": 50,
      "y": -1,
      "z": 26,
      "name": "Rock_Stone"
    },
    {
      "x": 50,
      "y": 0,
      "z": 26,
      "name": "Rock_Stone"
    },
    {
      "x": 50,
      "y": 1,
      "z": 26,
      "name": "Rock_Stone"
    },
    {
      "x": 50,
      "y": 2,
      "z": 26,
      "name": "Rock_Stone"
    },
    {
      "x": 50,
      "y": 3,
      "z": 26,
      "name": "Rock_Basalt"
    },
    {
      "x": 50,
      "y": 4,
      "z": 26,
      "name": "Rock_Stone"
    },
    {
      "x": 50,
      "y": 5,
      "z": 26,
      "name": "Rock_Stone"
    },
    {
      "x": 50,
      "y": 6,
      "z": 26,
      "name": "Rock_Basalt_Cobble"
    },
    {
      "x": 50,
      "y": 7,
      "z": 26,
      "name": "Rock_Basalt_Cobble"
    },
    {
      "x": 50,
      "y": 8,
      "z": 26,
      "name": "Rock_Basalt"
    },
    {
      "x": 50,
      "y": 9,
      "z": 26,
      "name": "Rock_Basalt_Cobble"
    },
    {
      "x": 50,
      "y": 10,
      "z": 26,
      "name": "Rock_Basalt_Cobble"
    },
    {
      "x": 50,
      "y": 11,
      "z": 26,
      "name": "Rock_Basalt_Cobble"
    },
    {
      "x": 50,
      "y": 12,
      "z": 26,
      "name": "Rock_Stone"
    },
    {
      "x": 50,
      "y": 13,
      "z": 26,
      "name": "Rock_Basalt_Cobble"
    },
    {
      "x": 50,
      "y": 14,
      "z": 26,
      "name": "Rock_Basalt"
    },
    {
      "x": 50,
      "y": 15,
      "z": 26,
      "name": "Soil_Gravel"
    },
    {
      "x": 50,
      "y": 16,
      "z": 26,
      "name": "Rock_Basalt"
    },
    {
      "x": 50,
      "y": 17,
      "z": 26,
      "name": "Soil_Gravel"
    },
    {
      "x": 50,
      "y": 18,
      "z": 26,
      "name": "Rock_Basalt"
    },
    {
      "x": 50,
      "y": 19,
      "z": 26,
      "name": "Rock_Basalt"
    },
    {
      "x": 50,
      "y": 20,
      "z": 26,
      "name": "Rock_Basalt"
    },
    {
      "x": 50,
      "y": 21,
      "z": 26,
      "name": "Rock_Stone"
    },
    {
      "x": 50,
      "y": 22,
      "z": 26,
      "name": "Soil_Gravel"
    },
    {
      "x": 50,
      "y": -9,
      "z": 27,
      "name": "Rock_Stone"
    },
    {
      "x": 50,
      "y": -8,
      "z": 27,
      "name": "Rock_Stone"
    },
    {
      "x": 50,
      "y": -7,
      "z": 27,
      "name": "Rock_Stone"
    },
    {
      "x": 50,
      "y": -6,
      "z": 27,
      "name": "Rock_Stone"
    },
    {
      "x": 50,
      "y": -5,
      "z": 27,
      "name": "Rock_Stone"
    },
    {
      "x": 50,
      "y": -4,
      "z": 27,
      "name": "Rock_Stone"
    },
    {
      "x": 50,
      "y": -3,
      "z": 27,
      "name": "Rock_Stone"
    },
    {
      "x": 50,
      "y": -2,
      "z": 27,
      "name": "Rock_Stone"
    },
    {
      "x": 50,
      "y": -1,
      "z": 27,
      "name": "Rock_Stone"
    },
    {
      "x": 50,
      "y": 0,
      "z": 27,
      "name": "Rock_Stone"
    },
    {
      "x": 50,
      "y": 1,
      "z": 27,
      "name": "Rock_Stone"
    },
    {
      "x": 50,
      "y": 2,
      "z": 27,
      "name": "Rock_Stone"
    },
    {
      "x": 50,
      "y": 3,
      "z": 27,
      "name": "Rock_Basalt"
    },
    {
      "x": 50,
      "y": 4,
      "z": 27,
      "name": "Rock_Basalt_Cobble"
    },
    {
      "x": 50,
      "y": 5,
      "z": 27,
      "name": "Rock_Stone"
    },
    {
      "x": 50,
      "y": 6,
      "z": 27,
      "name": "Ore_Copper_Stone"
    },
    {
      "x": 50,
      "y": 7,
      "z": 27,
      "name": "Rock_Basalt"
    },
    {
      "x": 50,
      "y": 8,
      "z": 27,
      "name": "Rock_Basalt"
    },
    {
      "x": 50,
      "y": 9,
      "z": 27,
      "name": "Soil_Gravel"
    },
    {
      "x": 50,
      "y": 10,
      "z": 27,
      "name": "Soil_Gravel"
    },
    {
      "x": 50,
      "y": 11,
      "z": 27,
      "name": "Ore_Copper_Stone"
    },
    {
      "x": 50,
      "y": 12,
      "z": 27,
      "name": "Rock_Basalt_Cobble"
    },
    {
      "x": 50,
      "y": 13,
      "z": 27,
      "name": "Rock_Basalt"
    },
    {
      "x": 50,
      "y": 14,
      "z": 27,
      "name": "Rock_Basalt"
    },
    {
      "x": 50,
      "y": 15,
      "z": 27,
      "name": "Rock_Basalt"
    },
    {
      "x": 50,
      "y": 16,
      "z": 27,
      "name": "Rock_Stone"
    },
    {
      "x": 50,
      "y": 17,
      "z": 27,
      "name": "Rock_Basalt"
    },
    {
      "x": 50,
      "y": 18,
      "z": 27,
      "name": "Rock_Basalt_Cobble"
    },
    {
      "x": 50,
      "y": 19,
      "z": 27,
      "name": "Rock_Basalt_Cobble"
    },
    {
      "x": 50,
      "y": 20,
      "z": 27,
      "name": "Soil_Gravel"
    },
    {
      "x": 50,
      "y": 21,
      "z": 27,
      "name": "Rock_Basalt"
    },
    {
      "x": 50,
      "y": 22,
      "z": 27,
      "name": "Rock_Basalt_Cobble"
    },
    {
      "x": 50,
      "y": -9,
      "z": 28,
      "name": "Rock_Stone"
    },
    {
      "x": 50,
      "y": -8,
      "z": 28,
      "name": "Rock_Stone"
    },
    {
      "x": 50,
      "y": -7,
      "z": 28,
      "name": "Rock_Stone"
    },
    {
      "x": 50,
      "y": -6,
      "z": 28,
      "name": "Rock_Stone"
    },
    {
      "x": 50,
      "y": -5,
      "z": 28,
      "name": "Rock_Stone"
    },
    {
      "x": 50,
      "y": -4,
      "z": 28,
      "name": "Rock_Stone"
    },
    {
      "x": 50,
      "y": -3,
      "z": 28,
      "name": "Rock_Stone"
    },
    {
      "x": 50,
      "y": -2,
      "z": 28,
      "name": "Rock_Stone"
    },
    {
      "x": 50,
      "y": -1,
      "z": 28,
      "name": "Rock_Stone"
    },
    {
      "x": 50,
      "y": 0,
      "z": 28,
      "name": "Rock_Stone"
    },
    {
      "x": 50,
      "y": 1,
      "z": 28,
      "name": "Rock_Stone"
    },
    {
      "x": 50,
      "y": 2,
      "z": 28,
      "name": "Rock_Stone"
    },
    {
      "x": 50,
      "y": 3,
      "z": 28,
      "name": "Soil_Gravel"
    },
    {
      "x": 50,
      "y": 4,
      "z": 28,
      "name": "Rock_Stone"
    },
    {
      "x": 50,
      "y": 5,
      "z": 28,
      "name": "Rock_Basalt"
    },
    {
      "x": 50,
      "y": 6,
      "z": 28,
      "name": "Rock_Basalt_Cobble"
    },
    {
      "x": 50,
      "y": 7,
      "z": 28,
      "name": "Rock_Basalt"
    },
    {
      "x": 50,
      "y": 8,
      "z": 28,
      "name": "Rock_Basalt"
    },
    {
      "x": 50,
      "y": 9,
      "z": 28,
      "name": "Soil_Gravel"
    },
    {
      "x": 50,
      "y": 10,
      "z": 28,
      "name": "Rock_Basalt_Cobble"
    },
    {
      "x": 50,
      "y": 11,
      "z": 28,
      "name": "Rock_Basalt_Cobble"
    },
    {
      "x": 50,
      "y": 12,
      "z": 28,
      "name": "Rock_Basalt_Cobble"
    },
    {
      "x": 50,
      "y": 13,
      "z": 28,
      "name": "Rock_Basalt"
    },
    {
      "x": 50,
      "y": 14,
      "z": 28,
      "name": "Rock_Basalt"
    },
    {
      "x": 50,
      "y": 15,
      "z": 28,
      "name": "Rock_Stone"
    },
    {
      "x": 50,
      "y": 16,
      "z": 28,
      "name": "Rock_Basalt"
    },
    {
      "x": 50,
      "y": 17,
      "z": 28,
      "name": "Rock_Basalt"
    },
    {
      "x": 50,
      "y": 18,
      "z": 28,
      "name": "Soil_Gravel"
    },
    {
      "x": 50,
      "y": 19,
      "z": 28,
      "name": "Rock_Stone"
    },
    {
      "x": 50,
      "y": 20,
      "z": 28,
      "name": "Soil_Gravel"
    },
    {
      "x": 50,
      "y": 21,
      "z": 28,
      "name": "Soil_Gravel"
    },
    {
      "x": 50,
      "y": 22,
      "z": 28,
      "name": "Rock_Basalt"
    },
    {
      "x": 50,
      "y": -9,
      "z": 29,
      "name": "Rock_Stone"
    },
    {
      "x": 50,
      "y": -8,
      "z": 29,
      "name": "Rock_Stone"
    },
    {
      "x": 50,
      "y": -7,
      "z": 29,
      "name": "Rock_Stone"
    },
    {
      "x": 50,
      "y": -6,
      "z": 29,
      "name": "Rock_Stone"
    },
    {
      "x": 50,
      "y": -5,
      "z": 29,
      "name": "Rock_Stone"
    },
    {
      "x": 50,
      "y": -4,
      "z": 29,
      "name": "Rock_Stone"
    },
    {
      "x": 50,
      "y": -3,
      "z": 29,
      "name": "Rock_Stone"
    },
    {
      "x": 50,
      "y": -2,
      "z": 29,
      "name": "Rock_Stone"
    },
    {
      "x": 50,
      "y": -1,
      "z": 29,
      "name": "Rock_Stone"
    },
    {
      "x": 50,
      "y": 0,
      "z": 29,
      "name": "Rock_Stone"
    },
    {
      "x": 50,
      "y": 1,
      "z": 29,
      "name": "Rock_Stone"
    },
    {
      "x": 50,
      "y": 2,
      "z": 29,
      "name": "Rock_Stone"
    },
    {
      "x": 50,
      "y": 3,
      "z": 29,
      "name": "Rock_Stone"
    },
    {
      "x": 50,
      "y": 4,
      "z": 29,
      "name": "Rock_Basalt_Cobble"
    },
    {
      "x": 50,
      "y": 5,
      "z": 29,
      "name": "Rock_Basalt"
    },
    {
      "x": 50,
      "y": 6,
      "z": 29,
      "name": "Rock_Basalt"
    },
    {
      "x": 50,
      "y": 7,
      "z": 29,
      "name": "Soil_Gravel"
    },
    {
      "x": 50,
      "y": 8,
      "z": 29,
      "name": "Rock_Stone"
    },
    {
      "x": 50,
      "y": 9,
      "z": 29,
      "name": "Soil_Gravel"
    },
    {
      "x": 50,
      "y": 10,
      "z": 29,
      "name": "Soil_Gravel"
    },
    {
      "x": 50,
      "y": 11,
      "z": 29,
      "name": "Rock_Basalt"
    },
    {
      "x": 50,
      "y": 12,
      "z": 29,
      "name": "Rock_Basalt"
    },
    {
      "x": 50,
      "y": 13,
      "z": 29,
      "name": "Soil_Gravel"
    },
    {
      "x": 50,
      "y": 14,
      "z": 29,
      "name": "Rock_Basalt_Cobble"
    },
    {
      "x": 50,
      "y": 15,
      "z": 29,
      "name": "Soil_Gravel"
    },
    {
      "x": 50,
      "y": 16,
      "z": 29,
      "name": "Empty"
    },
    {
      "x": 50,
      "y": 17,
      "z": 29,
      "name": "Rock_Basalt"
    },
    {
      "x": 50,
      "y": 18,
      "z": 29,
      "name": "Soil_Gravel"
    },
    {
      "x": 50,
      "y": 19,
      "z": 29,
      "name": "Rock_Basalt"
    },
    {
      "x": 50,
      "y": 20,
      "z": 29,
      "name": "Rock_Stone"
    },
    {
      "x": 50,
      "y": 21,
      "z": 29,
      "name": "Rock_Basalt_Cobble"
    },
    {
      "x": 50,
      "y": 22,
      "z": 29,
      "name": "Rock_Stone"
    },
    {
      "x": 50,
      "y": -9,
      "z": 30,
      "name": "Rock_Stone"
    },
    {
      "x": 50,
      "y": -8,
      "z": 30,
      "name": "Rock_Stone"
    },
    {
      "x": 50,
      "y": -7,
      "z": 30,
      "name": "Rock_Stone"
    },
    {
      "x": 50,
      "y": -6,
      "z": 30,
      "name": "Rock_Stone"
    },
    {
      "x": 50,
      "y": -5,
      "z": 30,
      "name": "Rock_Stone"
    },
    {
      "x": 50,
      "y": -4,
      "z": 30,
      "name": "Rock_Stone"
    },
    {
      "x": 50,
      "y": -3,
      "z": 30,
      "name": "Rock_Stone"
    },
    {
      "x": 50,
      "y": -2,
      "z": 30,
      "name": "Rock_Stone"
    },
    {
      "x": 50,
      "y": -1,
      "z": 30,
      "name": "Rock_Stone"
    },
    {
      "x": 50,
      "y": 0,
      "z": 30,
      "name": "Rock_Stone"
    },
    {
      "x": 50,
      "y": 1,
      "z": 30,
      "name": "Rock_Stone"
    },
    {
      "x": 50,
      "y": 2,
      "z": 30,
      "name": "Rock_Stone"
    },
    {
      "x": 50,
      "y": 3,
      "z": 30,
      "name": "Rock_Basalt"
    },
    {
      "x": 50,
      "y": 4,
      "z": 30,
      "name": "Rock_Basalt_Cobble"
    },
    {
      "x": 50,
      "y": 5,
      "z": 30,
      "name": "Rock_Basalt_Cobble"
    },
    {
      "x": 50,
      "y": 6,
      "z": 30,
      "name": "Rock_Basalt_Cobble"
    },
    {
      "x": 50,
      "y": 7,
      "z": 30,
      "name": "Rock_Stone"
    },
    {
      "x": 50,
      "y": 8,
      "z": 30,
      "name": "Rock_Basalt_Cobble"
    },
    {
      "x": 50,
      "y": 9,
      "z": 30,
      "name": "Rock_Basalt"
    },
    {
      "x": 50,
      "y": 10,
      "z": 30,
      "name": "Rock_Basalt"
    },
    {
      "x": 50,
      "y": 11,
      "z": 30,
      "name": "Rock_Stone"
    },
    {
      "x": 50,
      "y": 12,
      "z": 30,
      "name": "Rock_Stone"
    },
    {
      "x": 50,
      "y": 13,
      "z": 30,
      "name": "Rock_Stone"
    },
    {
      "x": 50,
      "y": 14,
      "z": 30,
      "name": "Plant_Crop_Mushroom_Block_Red_Trunk"
    },
    {
      "x": 50,
      "y": 15,
      "z": 30,
      "name": "Rock_Basalt_Cobble"
    },
    {
      "x": 50,
      "y": 16,
      "z": 30,
      "name": "Empty"
    },
    {
      "x": 50,
      "y": 17,
      "z": 30,
      "name": "Empty"
    },
    {
      "x": 50,
      "y": 18,
      "z": 30,
      "name": "Soil_Gravel"
    },
    {
      "x": 50,
      "y": 19,
      "z": 30,
      "name": "Rock_Stone"
    },
    {
      "x": 50,
      "y": 20,
      "z": 30,
      "name": "Rock_Basalt_Cobble"
    },
    {
      "x": 50,
      "y": 21,
      "z": 30,
      "name": "Rock_Basalt_Cobble"
    },
    {
      "x": 50,
      "y": 22,
      "z": 30,
      "name": "Rock_Basalt_Cobble"
    },
    {
      "x": 50,
      "y": -9,
      "z": 31,
      "name": "Rock_Stone"
    },
    {
      "x": 50,
      "y": -8,
      "z": 31,
      "name": "Rock_Stone"
    },
    {
      "x": 50,
      "y": -7,
      "z": 31,
      "name": "Rock_Stone"
    },
    {
      "x": 50,
      "y": -6,
      "z": 31,
      "name": "Rock_Stone"
    },
    {
      "x": 50,
      "y": -5,
      "z": 31,
      "name": "Rock_Stone"
    },
    {
      "x": 50,
      "y": -4,
      "z": 31,
      "name": "Rock_Stone"
    },
    {
      "x": 50,
      "y": -3,
      "z": 31,
      "name": "Rock_Stone"
    },
    {
      "x": 50,
      "y": -2,
      "z": 31,
      "name": "Rock_Stone"
    },
    {
      "x": 50,
      "y": -1,
      "z": 31,
      "name": "Rock_Stone"
    },
    {
      "x": 50,
      "y": 0,
      "z": 31,
      "name": "Rock_Stone"
    },
    {
      "x": 50,
      "y": 1,
      "z": 31,
      "name": "Rock_Stone"
    },
    {
      "x": 50,
      "y": 2,
      "z": 31,
      "name": "Rock_Stone"
    },
    {
      "x": 50,
      "y": 3,
      "z": 31,
      "name": "Rock_Basalt"
    },
    {
      "x": 50,
      "y": 4,
      "z": 31,
      "name": "Soil_Gravel"
    },
    {
      "x": 50,
      "y": 5,
      "z": 31,
      "name": "Rock_Stone"
    },
    {
      "x": 50,
      "y": 6,
      "z": 31,
      "name": "Rock_Stone"
    },
    {
      "x": 50,
      "y": 7,
      "z": 31,
      "name": "Rock_Stone"
    },
    {
      "x": 50,
      "y": 8,
      "z": 31,
      "name": "Rock_Basalt_Cobble"
    },
    {
      "x": 50,
      "y": 9,
      "z": 31,
      "name": "Rock_Basalt"
    },
    {
      "x": 50,
      "y": 10,
      "z": 31,
      "name": "Rock_Basalt"
    },
    {
      "x": 50,
      "y": 11,
      "z": 31,
      "name": "Rock_Basalt_Cobble"
    },
    {
      "x": 50,
      "y": 12,
      "z": 31,
      "name": "Rock_Basalt_Cobble"
    },
    {
      "x": 50,
      "y": 13,
      "z": 31,
      "name": "Rock_Basalt_Cobble"
    },
    {
      "x": 50,
      "y": 14,
      "z": 31,
      "name": "Empty"
    },
    {
      "x": 50,
      "y": 15,
      "z": 31,
      "name": "Rock_Basalt"
    },
    {
      "x": 50,
      "y": 16,
      "z": 31,
      "name": "Empty"
    },
    {
      "x": 50,
      "y": 17,
      "z": 31,
      "name": "Empty"
    },
    {
      "x": 50,
      "y": 18,
      "z": 31,
      "name": "Soil_Gravel"
    },
    {
      "x": 50,
      "y": 19,
      "z": 31,
      "name": "Rock_Basalt"
    },
    {
      "x": 50,
      "y": 20,
      "z": 31,
      "name": "Rock_Stone"
    },
    {
      "x": 50,
      "y": 21,
      "z": 31,
      "name": "Rock_Basalt"
    },
    {
      "x": 50,
      "y": 22,
      "z": 31,
      "name": "Rock_Basalt"
    },
    {
      "x": 50,
      "y": -9,
      "z": 32,
      "name": "Rock_Stone"
    },
    {
      "x": 50,
      "y": -8,
      "z": 32,
      "name": "Rock_Stone"
    },
    {
      "x": 50,
      "y": -7,
      "z": 32,
      "name": "Rock_Stone"
    },
    {
      "x": 50,
      "y": -6,
      "z": 32,
      "name": "Rock_Stone"
    },
    {
      "x": 50,
      "y": -5,
      "z": 32,
      "name": "Rock_Stone"
    },
    {
      "x": 50,
      "y": -4,
      "z": 32,
      "name": "Rock_Stone"
    },
    {
      "x": 50,
      "y": -3,
      "z": 32,
      "name": "Rock_Stone"
    },
    {
      "x": 50,
      "y": -2,
      "z": 32,
      "name": "Rock_Stone"
    },
    {
      "x": 50,
      "y": -1,
      "z": 32,
      "name": "Ore_Iron_Stone"
    },
    {
      "x": 50,
      "y": 0,
      "z": 32,
      "name": "Rock_Stone"
    },
    {
      "x": 50,
      "y": 1,
      "z": 32,
      "name": "Rock_Stone"
    },
    {
      "x": 50,
      "y": 2,
      "z": 32,
      "name": "Rock_Stone"
    },
    {
      "x": 50,
      "y": 3,
      "z": 32,
      "name": "Ore_Iron_Basalt"
    },
    {
      "x": 50,
      "y": 4,
      "z": 32,
      "name": "Rock_Basalt"
    },
    {
      "x": 50,
      "y": 5,
      "z": 32,
      "name": "Rock_Basalt"
    },
    {
      "x": 50,
      "y": 6,
      "z": 32,
      "name": "Soil_Gravel"
    },
    {
      "x": 50,
      "y": 7,
      "z": 32,
      "name": "Rock_Basalt_Cobble"
    },
    {
      "x": 50,
      "y": 8,
      "z": 32,
      "name": "Soil_Gravel"
    },
    {
      "x": 50,
      "y": 9,
      "z": 32,
      "name": "Rock_Basalt"
    },
    {
      "x": 50,
      "y": 10,
      "z": 32,
      "name": "Soil_Gravel"
    },
    {
      "x": 50,
      "y": 11,
      "z": 32,
      "name": "Rock_Basalt"
    },
    {
      "x": 50,
      "y": 12,
      "z": 32,
      "name": "Rock_Basalt"
    },
    {
      "x": 50,
      "y": 13,
      "z": 32,
      "name": "Rock_Basalt"
    },
    {
      "x": 50,
      "y": 14,
      "z": 32,
      "name": "Rock_Basalt"
    },
    {
      "x": 50,
      "y": 15,
      "z": 32,
      "name": "Rock_Basalt_Cobble"
    },
    {
      "x": 50,
      "y": 16,
      "z": 32,
      "name": "Rock_Basalt"
    },
    {
      "x": 50,
      "y": 17,
      "z": 32,
      "name": "Rock_Basalt"
    },
    {
      "x": 50,
      "y": 18,
      "z": 32,
      "name": "Soil_Gravel"
    },
    {
      "x": 50,
      "y": 19,
      "z": 32,
      "name": "Ore_Copper_Stone"
    },
    {
      "x": 50,
      "y": 20,
      "z": 32,
      "name": "Soil_Gravel"
    },
    {
      "x": 50,
      "y": 21,
      "z": 32,
      "name": "Soil_Gravel"
    },
    {
      "x": 50,
      "y": 22,
      "z": 32,
      "name": "Rock_Stone"
    },
    {
      "x": 50,
      "y": -9,
      "z": 33,
      "name": "Rock_Stone"
    },
    {
      "x": 50,
      "y": -8,
      "z": 33,
      "name": "Rock_Stone"
    },
    {
      "x": 50,
      "y": -7,
      "z": 33,
      "name": "Rock_Stone"
    },
    {
      "x": 50,
      "y": -6,
      "z": 33,
      "name": "Rock_Stone"
    },
    {
      "x": 50,
      "y": -5,
      "z": 33,
      "name": "Rock_Stone"
    },
    {
      "x": 50,
      "y": -4,
      "z": 33,
      "name": "Rock_Stone"
    },
    {
      "x": 50,
      "y": -3,
      "z": 33,
      "name": "Rock_Stone"
    },
    {
      "x": 50,
      "y": -2,
      "z": 33,
      "name": "Rock_Stone"
    },
    {
      "x": 50,
      "y": -1,
      "z": 33,
      "name": "Rock_Stone"
    },
    {
      "x": 50,
      "y": 0,
      "z": 33,
      "name": "Rock_Stone"
    },
    {
      "x": 50,
      "y": 1,
      "z": 33,
      "name": "Rock_Stone"
    },
    {
      "x": 50,
      "y": 2,
      "z": 33,
      "name": "Rock_Stone"
    },
    {
      "x": 50,
      "y": 3,
      "z": 33,
      "name": "Rock_Basalt"
    },
    {
      "x": 50,
      "y": 4,
      "z": 33,
      "name": "Soil_Gravel"
    },
    {
      "x": 50,
      "y": 5,
      "z": 33,
      "name": "Rock_Stone"
    },
    {
      "x": 50,
      "y": 6,
      "z": 33,
      "name": "Soil_Gravel"
    },
    {
      "x": 50,
      "y": 7,
      "z": 33,
      "name": "Soil_Gravel"
    },
    {
      "x": 50,
      "y": 8,
      "z": 33,
      "name": "Soil_Gravel"
    },
    {
      "x": 50,
      "y": 9,
      "z": 33,
      "name": "Soil_Gravel"
    },
    {
      "x": 50,
      "y": 10,
      "z": 33,
      "name": "Soil_Gravel"
    },
    {
      "x": 50,
      "y": 11,
      "z": 33,
      "name": "Rock_Basalt_Cobble"
    },
    {
      "x": 50,
      "y": 12,
      "z": 33,
      "name": "Rock_Basalt_Cobble"
    },
    {
      "x": 50,
      "y": 13,
      "z": 33,
      "name": "Rock_Basalt_Cobble"
    },
    {
      "x": 50,
      "y": 14,
      "z": 33,
      "name": "Rock_Basalt"
    },
    {
      "x": 50,
      "y": 15,
      "z": 33,
      "name": "Rock_Stone"
    },
    {
      "x": 50,
      "y": 16,
      "z": 33,
      "name": "Rock_Basalt_Cobble"
    },
    {
      "x": 50,
      "y": 17,
      "z": 33,
      "name": "Rock_Stone"
    },
    {
      "x": 50,
      "y": 18,
      "z": 33,
      "name": "Rock_Basalt"
    },
    {
      "x": 50,
      "y": 19,
      "z": 33,
      "name": "Rock_Basalt_Cobble"
    },
    {
      "x": 50,
      "y": 20,
      "z": 33,
      "name": "Rock_Basalt_Cobble"
    },
    {
      "x": 50,
      "y": 21,
      "z": 33,
      "name": "Rock_Basalt"
    },
    {
      "x": 50,
      "y": 22,
      "z": 33,
      "name": "Soil_Gravel"
    },
    {
      "x": 50,
      "y": -9,
      "z": 34,
      "name": "Rock_Stone"
    },
    {
      "x": 50,
      "y": -8,
      "z": 34,
      "name": "Rock_Stone"
    },
    {
      "x": 50,
      "y": -7,
      "z": 34,
      "name": "Rock_Stone"
    },
    {
      "x": 50,
      "y": -6,
      "z": 34,
      "name": "Rock_Stone"
    },
    {
      "x": 50,
      "y": -5,
      "z": 34,
      "name": "Rock_Stone"
    },
    {
      "x": 50,
      "y": -4,
      "z": 34,
      "name": "Rock_Stone"
    },
    {
      "x": 50,
      "y": -3,
      "z": 34,
      "name": "Rock_Stone"
    },
    {
      "x": 50,
      "y": -2,
      "z": 34,
      "name": "Rock_Stone"
    },
    {
      "x": 50,
      "y": -1,
      "z": 34,
      "name": "Rock_Stone"
    },
    {
      "x": 50,
      "y": 0,
      "z": 34,
      "name": "Rock_Stone"
    },
    {
      "x": 50,
      "y": 1,
      "z": 34,
      "name": "Rock_Stone"
    },
    {
      "x": 50,
      "y": 2,
      "z": 34,
      "name": "Rock_Stone"
    },
    {
      "x": 50,
      "y": 3,
      "z": 34,
      "name": "Soil_Gravel"
    },
    {
      "x": 50,
      "y": 4,
      "z": 34,
      "name": "Soil_Gravel"
    },
    {
      "x": 50,
      "y": 5,
      "z": 34,
      "name": "Rock_Basalt_Cobble"
    },
    {
      "x": 50,
      "y": 6,
      "z": 34,
      "name": "Soil_Gravel"
    },
    {
      "x": 50,
      "y": 7,
      "z": 34,
      "name": "Soil_Gravel"
    },
    {
      "x": 50,
      "y": 8,
      "z": 34,
      "name": "Rock_Stone"
    },
    {
      "x": 50,
      "y": 9,
      "z": 34,
      "name": "Rock_Stone"
    },
    {
      "x": 50,
      "y": 10,
      "z": 34,
      "name": "Rock_Basalt"
    },
    {
      "x": 50,
      "y": 11,
      "z": 34,
      "name": "Rock_Stone"
    },
    {
      "x": 50,
      "y": 12,
      "z": 34,
      "name": "Soil_Gravel"
    },
    {
      "x": 50,
      "y": 13,
      "z": 34,
      "name": "Soil_Gravel"
    },
    {
      "x": 50,
      "y": 14,
      "z": 34,
      "name": "Rock_Stone"
    },
    {
      "x": 50,
      "y": 15,
      "z": 34,
      "name": "Rock_Basalt_Cobble"
    },
    {
      "x": 50,
      "y": 16,
      "z": 34,
      "name": "Rock_Stone"
    },
    {
      "x": 50,
      "y": 17,
      "z": 34,
      "name": "Soil_Gravel"
    },
    {
      "x": 50,
      "y": 18,
      "z": 34,
      "name": "Rock_Basalt_Cobble"
    },
    {
      "x": 50,
      "y": 19,
      "z": 34,
      "name": "Rock_Stone"
    },
    {
      "x": 50,
      "y": 20,
      "z": 34,
      "name": "Rock_Basalt"
    },
    {
      "x": 50,
      "y": 21,
      "z": 34,
      "name": "Rock_Basalt_Cobble"
    },
    {
      "x": 50,
      "y": 22,
      "z": 34,
      "name": "Soil_Gravel"
    },
    {
      "x": 50,
      "y": -9,
      "z": 35,
      "name": "Rock_Stone"
    },
    {
      "x": 50,
      "y": -8,
      "z": 35,
      "name": "Rock_Stone"
    },
    {
      "x": 50,
      "y": -7,
      "z": 35,
      "name": "Rock_Stone"
    },
    {
      "x": 50,
      "y": -6,
      "z": 35,
      "name": "Rock_Stone"
    },
    {
      "x": 50,
      "y": -5,
      "z": 35,
      "name": "Rock_Stone"
    },
    {
      "x": 50,
      "y": -4,
      "z": 35,
      "name": "Rock_Stone"
    },
    {
      "x": 50,
      "y": -3,
      "z": 35,
      "name": "Rock_Stone"
    },
    {
      "x": 50,
      "y": -2,
      "z": 35,
      "name": "Rock_Stone"
    },
    {
      "x": 50,
      "y": -1,
      "z": 35,
      "name": "Rock_Stone"
    },
    {
      "x": 50,
      "y": 0,
      "z": 35,
      "name": "Rock_Stone"
    },
    {
      "x": 50,
      "y": 1,
      "z": 35,
      "name": "Rock_Stone"
    },
    {
      "x": 50,
      "y": 2,
      "z": 35,
      "name": "Rock_Stone"
    },
    {
      "x": 50,
      "y": 3,
      "z": 35,
      "name": "Soil_Gravel"
    },
    {
      "x": 50,
      "y": 4,
      "z": 35,
      "name": "Soil_Gravel"
    },
    {
      "x": 50,
      "y": 5,
      "z": 35,
      "name": "Soil_Gravel"
    },
    {
      "x": 50,
      "y": 6,
      "z": 35,
      "name": "Rock_Basalt_Cobble"
    },
    {
      "x": 50,
      "y": 7,
      "z": 35,
      "name": "Rock_Stone"
    },
    {
      "x": 50,
      "y": 8,
      "z": 35,
      "name": "Rock_Basalt"
    },
    {
      "x": 50,
      "y": 9,
      "z": 35,
      "name": "Rock_Stone"
    },
    {
      "x": 50,
      "y": 10,
      "z": 35,
      "name": "Rock_Basalt_Cobble"
    },
    {
      "x": 50,
      "y": 11,
      "z": 35,
      "name": "Rock_Basalt_Cobble"
    },
    {
      "x": 50,
      "y": 12,
      "z": 35,
      "name": "Rock_Basalt"
    },
    {
      "x": 50,
      "y": 13,
      "z": 35,
      "name": "Rock_Basalt"
    },
    {
      "x": 50,
      "y": 14,
      "z": 35,
      "name": "Rock_Stone"
    },
    {
      "x": 50,
      "y": 15,
      "z": 35,
      "name": "Rock_Basalt"
    },
    {
      "x": 50,
      "y": 16,
      "z": 35,
      "name": "Rock_Basalt"
    },
    {
      "x": 50,
      "y": 17,
      "z": 35,
      "name": "Ore_Copper_Stone"
    },
    {
      "x": 50,
      "y": 18,
      "z": 35,
      "name": "Rock_Basalt"
    },
    {
      "x": 50,
      "y": 19,
      "z": 35,
      "name": "Soil_Gravel"
    },
    {
      "x": 50,
      "y": 20,
      "z": 35,
      "name": "Rock_Stone"
    },
    {
      "x": 50,
      "y": -9,
      "z": 36,
      "name": "Rock_Stone"
    },
    {
      "x": 50,
      "y": -8,
      "z": 36,
      "name": "Rock_Stone"
    },
    {
      "x": 50,
      "y": -7,
      "z": 36,
      "name": "Rock_Stone"
    },
    {
      "x": 50,
      "y": -6,
      "z": 36,
      "name": "Rock_Stone"
    },
    {
      "x": 50,
      "y": -5,
      "z": 36,
      "name": "Rock_Stone"
    },
    {
      "x": 50,
      "y": -4,
      "z": 36,
      "name": "Rock_Stone"
    },
    {
      "x": 50,
      "y": -3,
      "z": 36,
      "name": "Rock_Stone"
    },
    {
      "x": 50,
      "y": -2,
      "z": 36,
      "name": "Rock_Stone"
    },
    {
      "x": 50,
      "y": -1,
      "z": 36,
      "name": "Rock_Stone"
    },
    {
      "x": 50,
      "y": 0,
      "z": 36,
      "name": "Rock_Stone"
    },
    {
      "x": 50,
      "y": 1,
      "z": 36,
      "name": "Rock_Basalt"
    },
    {
      "x": 50,
      "y": 2,
      "z": 36,
      "name": "Soil_Gravel"
    },
    {
      "x": 50,
      "y": 3,
      "z": 36,
      "name": "Rock_Stone"
    },
    {
      "x": 50,
      "y": 4,
      "z": 36,
      "name": "Rock_Basalt"
    },
    {
      "x": 50,
      "y": 5,
      "z": 36,
      "name": "Soil_Gravel"
    },
    {
      "x": 50,
      "y": 6,
      "z": 36,
      "name": "Soil_Gravel"
    },
    {
      "x": 50,
      "y": 7,
      "z": 36,
      "name": "Rock_Basalt"
    },
    {
      "x": 50,
      "y": 8,
      "z": 36,
      "name": "Soil_Gravel"
    },
    {
      "x": 50,
      "y": 9,
      "z": 36,
      "name": "Soil_Gravel"
    },
    {
      "x": 50,
      "y": 10,
      "z": 36,
      "name": "Rock_Stone"
    },
    {
      "x": 50,
      "y": 11,
      "z": 36,
      "name": "Rock_Basalt_Cobble"
    },
    {
      "x": 50,
      "y": 12,
      "z": 36,
      "name": "Rock_Stone"
    },
    {
      "x": 50,
      "y": 13,
      "z": 36,
      "name": "Rock_Basalt"
    },
    {
      "x": 50,
      "y": 14,
      "z": 36,
      "name": "Rock_Basalt"
    },
    {
      "x": 50,
      "y": 15,
      "z": 36,
      "name": "Rock_Basalt"
    },
    {
      "x": 50,
      "y": 16,
      "z": 36,
      "name": "Rock_Basalt"
    },
    {
      "x": 50,
      "y": 17,
      "z": 36,
      "name": "Rock_Basalt"
    },
    {
      "x": 50,
      "y": 18,
      "z": 36,
      "name": "Rock_Stone"
    },
    {
      "x": 50,
      "y": 19,
      "z": 36,
      "name": "Rock_Basalt_Cobble"
    },
    {
      "x": 50,
      "y": 20,
      "z": 36,
      "name": "Rock_Basalt"
    },
    {
      "x": 50,
      "y": -9,
      "z": 37,
      "name": "Soil_Gravel"
    },
    {
      "x": 50,
      "y": -8,
      "z": 37,
      "name": "Rock_Basalt"
    },
    {
      "x": 50,
      "y": -7,
      "z": 37,
      "name": "Soil_Gravel"
    },
    {
      "x": 50,
      "y": -6,
      "z": 37,
      "name": "Rock_Basalt_Cobble"
    },
    {
      "x": 50,
      "y": -5,
      "z": 37,
      "name": "Rock_Basalt_Cobble"
    },
    {
      "x": 50,
      "y": -4,
      "z": 37,
      "name": "Soil_Gravel"
    },
    {
      "x": 50,
      "y": -3,
      "z": 37,
      "name": "Soil_Gravel"
    },
    {
      "x": 50,
      "y": -2,
      "z": 37,
      "name": "Rock_Basalt"
    },
    {
      "x": 50,
      "y": -1,
      "z": 37,
      "name": "Rock_Stone"
    },
    {
      "x": 50,
      "y": 0,
      "z": 37,
      "name": "Rock_Basalt_Cobble"
    },
    {
      "x": 50,
      "y": 1,
      "z": 37,
      "name": "Rock_Basalt_Cobble"
    },
    {
      "x": 50,
      "y": 2,
      "z": 37,
      "name": "Soil_Gravel"
    },
    {
      "x": 50,
      "y": 3,
      "z": 37,
      "name": "Rock_Stone"
    },
    {
      "x": 50,
      "y": 4,
      "z": 37,
      "name": "Rock_Basalt"
    },
    {
      "x": 50,
      "y": 5,
      "z": 37,
      "name": "Rock_Stone"
    },
    {
      "x": 50,
      "y": 6,
      "z": 37,
      "name": "Rock_Stone"
    },
    {
      "x": 50,
      "y": 7,
      "z": 37,
      "name": "Rock_Stone"
    },
    {
      "x": 50,
      "y": 8,
      "z": 37,
      "name": "Soil_Gravel"
    },
    {
      "x": 50,
      "y": 9,
      "z": 37,
      "name": "Soil_Gravel"
    },
    {
      "x": 50,
      "y": 10,
      "z": 37,
      "name": "Ore_Copper_Stone"
    },
    {
      "x": 50,
      "y": 11,
      "z": 37,
      "name": "Soil_Gravel"
    },
    {
      "x": 50,
      "y": 12,
      "z": 37,
      "name": "Rock_Basalt_Cobble"
    },
    {
      "x": 50,
      "y": 13,
      "z": 37,
      "name": "Rock_Basalt"
    },
    {
      "x": 50,
      "y": 14,
      "z": 37,
      "name": "Rock_Basalt"
    },
    {
      "x": 50,
      "y": 15,
      "z": 37,
      "name": "Rock_Basalt"
    },
    {
      "x": 50,
      "y": 16,
      "z": 37,
      "name": "Rock_Basalt"
    },
    {
      "x": 50,
      "y": 17,
      "z": 37,
      "name": "Rock_Basalt"
    },
    {
      "x": 50,
      "y": 18,
      "z": 37,
      "name": "Rock_Stone"
    },
    {
      "x": 50,
      "y": 19,
      "z": 37,
      "name": "Rock_Stone"
    },
    {
      "x": 51,
      "y": -9,
      "z": 24,
      "name": "Rock_Stone"
    },
    {
      "x": 51,
      "y": -8,
      "z": 24,
      "name": "Rock_Stone"
    },
    {
      "x": 51,
      "y": -7,
      "z": 24,
      "name": "Rock_Stone"
    },
    {
      "x": 51,
      "y": -6,
      "z": 24,
      "name": "Rock_Stone"
    },
    {
      "x": 51,
      "y": -5,
      "z": 24,
      "name": "Rock_Stone"
    },
    {
      "x": 51,
      "y": -4,
      "z": 24,
      "name": "Rock_Stone"
    },
    {
      "x": 51,
      "y": -3,
      "z": 24,
      "name": "Rock_Stone"
    },
    {
      "x": 51,
      "y": -2,
      "z": 24,
      "name": "Rock_Stone"
    },
    {
      "x": 51,
      "y": -1,
      "z": 24,
      "name": "Rock_Stone"
    },
    {
      "x": 51,
      "y": 0,
      "z": 24,
      "name": "Rock_Stone"
    },
    {
      "x": 51,
      "y": 1,
      "z": 24,
      "name": "Rock_Stone"
    },
    {
      "x": 51,
      "y": 2,
      "z": 24,
      "name": "Rock_Stone"
    },
    {
      "x": 51,
      "y": 3,
      "z": 24,
      "name": "Rock_Basalt"
    },
    {
      "x": 51,
      "y": 4,
      "z": 24,
      "name": "Soil_Gravel"
    },
    {
      "x": 51,
      "y": 5,
      "z": 24,
      "name": "Rock_Basalt_Cobble"
    },
    {
      "x": 51,
      "y": 6,
      "z": 24,
      "name": "Soil_Gravel"
    },
    {
      "x": 51,
      "y": 7,
      "z": 24,
      "name": "Rock_Basalt"
    },
    {
      "x": 51,
      "y": 8,
      "z": 24,
      "name": "Rock_Stone"
    },
    {
      "x": 51,
      "y": 9,
      "z": 24,
      "name": "Soil_Gravel"
    },
    {
      "x": 51,
      "y": 10,
      "z": 24,
      "name": "Soil_Gravel"
    },
    {
      "x": 51,
      "y": 11,
      "z": 24,
      "name": "Ore_Copper_Stone"
    },
    {
      "x": 51,
      "y": 12,
      "z": 24,
      "name": "Soil_Gravel"
    },
    {
      "x": 51,
      "y": 13,
      "z": 24,
      "name": "Rock_Stone"
    },
    {
      "x": 51,
      "y": 14,
      "z": 24,
      "name": "Rock_Basalt_Cobble"
    },
    {
      "x": 51,
      "y": 15,
      "z": 24,
      "name": "Rock_Basalt_Cobble"
    },
    {
      "x": 51,
      "y": 16,
      "z": 24,
      "name": "Soil_Gravel"
    },
    {
      "x": 51,
      "y": 17,
      "z": 24,
      "name": "Rock_Basalt"
    },
    {
      "x": 51,
      "y": 18,
      "z": 24,
      "name": "Rock_Basalt_Cobble"
    },
    {
      "x": 51,
      "y": 19,
      "z": 24,
      "name": "Soil_Gravel"
    },
    {
      "x": 51,
      "y": 20,
      "z": 24,
      "name": "Rock_Stone"
    },
    {
      "x": 51,
      "y": 21,
      "z": 24,
      "name": "Soil_Gravel"
    },
    {
      "x": 51,
      "y": -9,
      "z": 25,
      "name": "Rock_Stone"
    },
    {
      "x": 51,
      "y": -8,
      "z": 25,
      "name": "Rock_Stone"
    },
    {
      "x": 51,
      "y": -7,
      "z": 25,
      "name": "Rock_Stone"
    },
    {
      "x": 51,
      "y": -6,
      "z": 25,
      "name": "Rock_Stone"
    },
    {
      "x": 51,
      "y": -5,
      "z": 25,
      "name": "Rock_Stone"
    },
    {
      "x": 51,
      "y": -4,
      "z": 25,
      "name": "Rock_Stone"
    },
    {
      "x": 51,
      "y": -3,
      "z": 25,
      "name": "Rock_Stone"
    },
    {
      "x": 51,
      "y": -2,
      "z": 25,
      "name": "Rock_Stone"
    },
    {
      "x": 51,
      "y": -1,
      "z": 25,
      "name": "Rock_Stone"
    },
    {
      "x": 51,
      "y": 0,
      "z": 25,
      "name": "Rock_Stone"
    },
    {
      "x": 51,
      "y": 1,
      "z": 25,
      "name": "Rock_Stone"
    },
    {
      "x": 51,
      "y": 2,
      "z": 25,
      "name": "Rock_Stone"
    },
    {
      "x": 51,
      "y": 3,
      "z": 25,
      "name": "Rock_Stone"
    },
    {
      "x": 51,
      "y": 4,
      "z": 25,
      "name": "Rock_Basalt"
    },
    {
      "x": 51,
      "y": 5,
      "z": 25,
      "name": "Soil_Gravel"
    },
    {
      "x": 51,
      "y": 6,
      "z": 25,
      "name": "Soil_Gravel"
    },
    {
      "x": 51,
      "y": 7,
      "z": 25,
      "name": "Rock_Basalt"
    },
    {
      "x": 51,
      "y": 8,
      "z": 25,
      "name": "Rock_Stone"
    },
    {
      "x": 51,
      "y": 9,
      "z": 25,
      "name": "Rock_Basalt"
    },
    {
      "x": 51,
      "y": 10,
      "z": 25,
      "name": "Rock_Basalt"
    },
    {
      "x": 51,
      "y": 11,
      "z": 25,
      "name": "Rock_Stone"
    },
    {
      "x": 51,
      "y": 12,
      "z": 25,
      "name": "Soil_Gravel"
    },
    {
      "x": 51,
      "y": 13,
      "z": 25,
      "name": "Rock_Basalt_Cobble"
    },
    {
      "x": 51,
      "y": 14,
      "z": 25,
      "name": "Rock_Basalt_Cobble"
    },
    {
      "x": 51,
      "y": 15,
      "z": 25,
      "name": "Soil_Gravel"
    },
    {
      "x": 51,
      "y": 16,
      "z": 25,
      "name": "Rock_Basalt"
    },
    {
      "x": 51,
      "y": 17,
      "z": 25,
      "name": "Soil_Gravel"
    },
    {
      "x": 51,
      "y": 18,
      "z": 25,
      "name": "Rock_Basalt_Cobble"
    },
    {
      "x": 51,
      "y": 19,
      "z": 25,
      "name": "Rock_Stone"
    },
    {
      "x": 51,
      "y": 20,
      "z": 25,
      "name": "Rock_Stone"
    },
    {
      "x": 51,
      "y": 21,
      "z": 25,
      "name": "Rock_Basalt"
    },
    {
      "x": 51,
      "y": 22,
      "z": 25,
      "name": "Soil_Gravel"
    },
    {
      "x": 51,
      "y": -9,
      "z": 26,
      "name": "Rock_Stone"
    },
    {
      "x": 51,
      "y": -8,
      "z": 26,
      "name": "Rock_Stone"
    },
    {
      "x": 51,
      "y": -7,
      "z": 26,
      "name": "Rock_Stone"
    },
    {
      "x": 51,
      "y": -6,
      "z": 26,
      "name": "Rock_Stone"
    },
    {
      "x": 51,
      "y": -5,
      "z": 26,
      "name": "Rock_Stone"
    },
    {
      "x": 51,
      "y": -4,
      "z": 26,
      "name": "Rock_Stone"
    },
    {
      "x": 51,
      "y": -3,
      "z": 26,
      "name": "Rock_Stone"
    },
    {
      "x": 51,
      "y": -2,
      "z": 26,
      "name": "Rock_Stone"
    },
    {
      "x": 51,
      "y": -1,
      "z": 26,
      "name": "Rock_Stone"
    },
    {
      "x": 51,
      "y": 0,
      "z": 26,
      "name": "Rock_Stone"
    },
    {
      "x": 51,
      "y": 1,
      "z": 26,
      "name": "Rock_Stone"
    },
    {
      "x": 51,
      "y": 2,
      "z": 26,
      "name": "Rock_Stone"
    },
    {
      "x": 51,
      "y": 3,
      "z": 26,
      "name": "Soil_Gravel"
    },
    {
      "x": 51,
      "y": 4,
      "z": 26,
      "name": "Soil_Gravel"
    },
    {
      "x": 51,
      "y": 5,
      "z": 26,
      "name": "Soil_Gravel"
    },
    {
      "x": 51,
      "y": 6,
      "z": 26,
      "name": "Rock_Basalt"
    },
    {
      "x": 51,
      "y": 7,
      "z": 26,
      "name": "Soil_Gravel"
    },
    {
      "x": 51,
      "y": 8,
      "z": 26,
      "name": "Rock_Stone"
    },
    {
      "x": 51,
      "y": 9,
      "z": 26,
      "name": "Rock_Basalt"
    },
    {
      "x": 51,
      "y": 10,
      "z": 26,
      "name": "Rock_Stone"
    },
    {
      "x": 51,
      "y": 11,
      "z": 26,
      "name": "Rock_Stone"
    },
    {
      "x": 51,
      "y": 12,
      "z": 26,
      "name": "Rock_Basalt_Cobble"
    },
    {
      "x": 51,
      "y": 13,
      "z": 26,
      "name": "Rock_Basalt_Cobble"
    },
    {
      "x": 51,
      "y": 14,
      "z": 26,
      "name": "Rock_Stone"
    },
    {
      "x": 51,
      "y": 15,
      "z": 26,
      "name": "Rock_Stone"
    },
    {
      "x": 51,
      "y": 16,
      "z": 26,
      "name": "Rock_Basalt"
    },
    {
      "x": 51,
      "y": 17,
      "z": 26,
      "name": "Rock_Basalt"
    },
    {
      "x": 51,
      "y": 18,
      "z": 26,
      "name": "Rock_Basalt_Cobble"
    },
    {
      "x": 51,
      "y": 19,
      "z": 26,
      "name": "Ore_Iron_Basalt"
    },
    {
      "x": 51,
      "y": 20,
      "z": 26,
      "name": "Rock_Stone"
    },
    {
      "x": 51,
      "y": 21,
      "z": 26,
      "name": "Plant_Crop_Mushroom_Block_Red_Trunk"
    },
    {
      "x": 51,
      "y": 22,
      "z": 26,
      "name": "Plant_Crop_Mushroom_Block_Red_Trunk"
    },
    {
      "x": 51,
      "y": -9,
      "z": 27,
      "name": "Rock_Stone"
    },
    {
      "x": 51,
      "y": -8,
      "z": 27,
      "name": "Rock_Stone"
    },
    {
      "x": 51,
      "y": -7,
      "z": 27,
      "name": "Rock_Stone"
    },
    {
      "x": 51,
      "y": -6,
      "z": 27,
      "name": "Rock_Stone"
    },
    {
      "x": 51,
      "y": -5,
      "z": 27,
      "name": "Rock_Stone"
    },
    {
      "x": 51,
      "y": -4,
      "z": 27,
      "name": "Rock_Stone"
    },
    {
      "x": 51,
      "y": -3,
      "z": 27,
      "name": "Rock_Stone"
    },
    {
      "x": 51,
      "y": -2,
      "z": 27,
      "name": "Rock_Stone"
    },
    {
      "x": 51,
      "y": -1,
      "z": 27,
      "name": "Rock_Stone"
    },
    {
      "x": 51,
      "y": 0,
      "z": 27,
      "name": "Rock_Stone"
    },
    {
      "x": 51,
      "y": 1,
      "z": 27,
      "name": "Rock_Stone"
    },
    {
      "x": 51,
      "y": 2,
      "z": 27,
      "name": "Rock_Stone"
    },
    {
      "x": 51,
      "y": 3,
      "z": 27,
      "name": "Rock_Stone"
    },
    {
      "x": 51,
      "y": 4,
      "z": 27,
      "name": "Rock_Basalt_Cobble"
    },
    {
      "x": 51,
      "y": 5,
      "z": 27,
      "name": "Soil_Gravel"
    },
    {
      "x": 51,
      "y": 6,
      "z": 27,
      "name": "Rock_Basalt_Cobble"
    },
    {
      "x": 51,
      "y": 7,
      "z": 27,
      "name": "Rock_Basalt_Cobble"
    },
    {
      "x": 51,
      "y": 8,
      "z": 27,
      "name": "Rock_Stone"
    },
    {
      "x": 51,
      "y": 9,
      "z": 27,
      "name": "Rock_Basalt_Cobble"
    },
    {
      "x": 51,
      "y": 10,
      "z": 27,
      "name": "Rock_Stone"
    },
    {
      "x": 51,
      "y": 11,
      "z": 27,
      "name": "Rock_Basalt_Cobble"
    },
    {
      "x": 51,
      "y": 12,
      "z": 27,
      "name": "Ore_Copper_Stone"
    },
    {
      "x": 51,
      "y": 13,
      "z": 27,
      "name": "Rock_Basalt"
    },
    {
      "x": 51,
      "y": 14,
      "z": 27,
      "name": "Soil_Gravel"
    },
    {
      "x": 51,
      "y": 15,
      "z": 27,
      "name": "Ore_Copper_Stone"
    },
    {
      "x": 51,
      "y": 16,
      "z": 27,
      "name": "Rock_Basalt_Cobble"
    },
    {
      "x": 51,
      "y": 17,
      "z": 27,
      "name": "Rock_Stone"
    },
    {
      "x": 51,
      "y": 18,
      "z": 27,
      "name": "Rock_Stone"
    },
    {
      "x": 51,
      "y": 19,
      "z": 27,
      "name": "Rock_Basalt_Cobble"
    },
    {
      "x": 51,
      "y": 20,
      "z": 27,
      "name": "Rock_Basalt_Cobble"
    },
    {
      "x": 51,
      "y": 21,
      "z": 27,
      "name": "Plant_Crop_Mushroom_Block_Red_Trunk"
    },
    {
      "x": 51,
      "y": 22,
      "z": 27,
      "name": "Empty"
    },
    {
      "x": 51,
      "y": -9,
      "z": 28,
      "name": "Rock_Stone"
    },
    {
      "x": 51,
      "y": -8,
      "z": 28,
      "name": "Rock_Stone"
    },
    {
      "x": 51,
      "y": -7,
      "z": 28,
      "name": "Rock_Stone"
    },
    {
      "x": 51,
      "y": -6,
      "z": 28,
      "name": "Rock_Stone"
    },
    {
      "x": 51,
      "y": -5,
      "z": 28,
      "name": "Rock_Stone"
    },
    {
      "x": 51,
      "y": -4,
      "z": 28,
      "name": "Rock_Stone"
    },
    {
      "x": 51,
      "y": -3,
      "z": 28,
      "name": "Rock_Stone"
    },
    {
      "x": 51,
      "y": -2,
      "z": 28,
      "name": "Rock_Stone"
    },
    {
      "x": 51,
      "y": -1,
      "z": 28,
      "name": "Rock_Stone"
    },
    {
      "x": 51,
      "y": 0,
      "z": 28,
      "name": "Rock_Stone"
    },
    {
      "x": 51,
      "y": 1,
      "z": 28,
      "name": "Rock_Stone"
    },
    {
      "x": 51,
      "y": 2,
      "z": 28,
      "name": "Rock_Stone"
    },
    {
      "x": 51,
      "y": 3,
      "z": 28,
      "name": "Soil_Gravel"
    },
    {
      "x": 51,
      "y": 4,
      "z": 28,
      "name": "Rock_Basalt"
    },
    {
      "x": 51,
      "y": 5,
      "z": 28,
      "name": "Rock_Basalt_Cobble"
    },
    {
      "x": 51,
      "y": 6,
      "z": 28,
      "name": "Soil_Gravel"
    },
    {
      "x": 51,
      "y": 7,
      "z": 28,
      "name": "Rock_Stone"
    },
    {
      "x": 51,
      "y": 8,
      "z": 28,
      "name": "Rock_Stone"
    },
    {
      "x": 51,
      "y": 9,
      "z": 28,
      "name": "Soil_Gravel"
    },
    {
      "x": 51,
      "y": 10,
      "z": 28,
      "name": "Empty"
    },
    {
      "x": 51,
      "y": 11,
      "z": 28,
      "name": "Empty"
    },
    {
      "x": 51,
      "y": 12,
      "z": 28,
      "name": "Plant_Crop_Mushroom_Block_Red_Trunk"
    },
    {
      "x": 51,
      "y": 13,
      "z": 28,
      "name": "Plant_Crop_Mushroom_Block_Red_Trunk"
    },
    {
      "x": 51,
      "y": 14,
      "z": 28,
      "name": "Plant_Crop_Mushroom_Block_Red_Trunk"
    },
    {
      "x": 51,
      "y": 15,
      "z": 28,
      "name": "Empty"
    },
    {
      "x": 51,
      "y": 16,
      "z": 28,
      "name": "Empty"
    },
    {
      "x": 51,
      "y": 17,
      "z": 28,
      "name": "Empty"
    },
    {
      "x": 51,
      "y": 18,
      "z": 28,
      "name": "Rock_Basalt"
    },
    {
      "x": 51,
      "y": 19,
      "z": 28,
      "name": "Rock_Basalt_Cobble"
    },
    {
      "x": 51,
      "y": 20,
      "z": 28,
      "name": "Rock_Basalt"
    },
    {
      "x": 51,
      "y": 21,
      "z": 28,
      "name": "Plant_Crop_Mushroom_Block_Red_Trunk"
    },
    {
      "x": 51,
      "y": 22,
      "z": 28,
      "name": "Empty"
    },
    {
      "x": 51,
      "y": -9,
      "z": 29,
      "name": "Rock_Stone"
    },
    {
      "x": 51,
      "y": -8,
      "z": 29,
      "name": "Rock_Stone"
    },
    {
      "x": 51,
      "y": -7,
      "z": 29,
      "name": "Rock_Stone"
    },
    {
      "x": 51,
      "y": -6,
      "z": 29,
      "name": "Rock_Stone"
    },
    {
      "x": 51,
      "y": -5,
      "z": 29,
      "name": "Rock_Stone"
    },
    {
      "x": 51,
      "y": -4,
      "z": 29,
      "name": "Rock_Stone"
    },
    {
      "x": 51,
      "y": -3,
      "z": 29,
      "name": "Rock_Stone"
    },
    {
      "x": 51,
      "y": -2,
      "z": 29,
      "name": "Rock_Stone"
    },
    {
      "x": 51,
      "y": -1,
      "z": 29,
      "name": "Rock_Stone"
    },
    {
      "x": 51,
      "y": 0,
      "z": 29,
      "name": "Rock_Stone"
    },
    {
      "x": 51,
      "y": 1,
      "z": 29,
      "name": "Rock_Stone"
    },
    {
      "x": 51,
      "y": 2,
      "z": 29,
      "name": "Rock_Stone"
    },
    {
      "x": 51,
      "y": 3,
      "z": 29,
      "name": "Rock_Basalt_Cobble"
    },
    {
      "x": 51,
      "y": 4,
      "z": 29,
      "name": "Rock_Basalt"
    },
    {
      "x": 51,
      "y": 5,
      "z": 29,
      "name": "Rock_Basalt_Cobble"
    },
    {
      "x": 51,
      "y": 6,
      "z": 29,
      "name": "Empty"
    },
    {
      "x": 51,
      "y": 7,
      "z": 29,
      "name": "Empty"
    },
    {
      "x": 51,
      "y": 8,
      "z": 29,
      "name": "Empty"
    },
    {
      "x": 51,
      "y": 9,
      "z": 29,
      "name": "Empty"
    },
    {
      "x": 51,
      "y": 10,
      "z": 29,
      "name": "Empty"
    },
    {
      "x": 51,
      "y": 11,
      "z": 29,
      "name": "Empty"
    },
    {
      "x": 51,
      "y": 12,
      "z": 29,
      "name": "Plant_Crop_Mushroom_Block_Red_Trunk"
    },
    {
      "x": 51,
      "y": 13,
      "z": 29,
      "name": "Plant_Crop_Mushroom_Block_Red_Trunk"
    },
    {
      "x": 51,
      "y": 14,
      "z": 29,
      "name": "Plant_Crop_Mushroom_Block_Red_Trunk"
    },
    {
      "x": 51,
      "y": 15,
      "z": 29,
      "name": "Empty"
    },
    {
      "x": 51,
      "y": 16,
      "z": 29,
      "name": "Empty"
    },
    {
      "x": 51,
      "y": 17,
      "z": 29,
      "name": "Empty"
    },
    {
      "x": 51,
      "y": 18,
      "z": 29,
      "name": "Empty"
    },
    {
      "x": 51,
      "y": 19,
      "z": 29,
      "name": "Empty"
    },
    {
      "x": 51,
      "y": 20,
      "z": 29,
      "name": "Soil_Gravel"
    },
    {
      "x": 51,
      "y": 21,
      "z": 29,
      "name": "Empty"
    },
    {
      "x": 51,
      "y": 22,
      "z": 29,
      "name": "Empty"
    },
    {
      "x": 51,
      "y": -9,
      "z": 30,
      "name": "Rock_Stone"
    },
    {
      "x": 51,
      "y": -8,
      "z": 30,
      "name": "Rock_Stone"
    },
    {
      "x": 51,
      "y": -7,
      "z": 30,
      "name": "Rock_Stone"
    },
    {
      "x": 51,
      "y": -6,
      "z": 30,
      "name": "Rock_Stone"
    },
    {
      "x": 51,
      "y": -5,
      "z": 30,
      "name": "Rock_Stone"
    },
    {
      "x": 51,
      "y": -4,
      "z": 30,
      "name": "Rock_Stone"
    },
    {
      "x": 51,
      "y": -3,
      "z": 30,
      "name": "Rock_Stone"
    },
    {
      "x": 51,
      "y": -2,
      "z": 30,
      "name": "Rock_Stone"
    },
    {
      "x": 51,
      "y": -1,
      "z": 30,
      "name": "Rock_Stone"
    },
    {
      "x": 51,
      "y": 0,
      "z": 30,
      "name": "Rock_Stone"
    },
    {
      "x": 51,
      "y": 1,
      "z": 30,
      "name": "Rock_Stone"
    },
    {
      "x": 51,
      "y": 2,
      "z": 30,
      "name": "Rock_Stone"
    },
    {
      "x": 51,
      "y": 3,
      "z": 30,
      "name": "Soil_Gravel"
    },
    {
      "x": 51,
      "y": 4,
      "z": 30,
      "name": "Soil_Gravel"
    },
    {
      "x": 51,
      "y": 5,
      "z": 30,
      "name": "Empty"
    },
    {
      "x": 51,
      "y": 6,
      "z": 30,
      "name": "Plant_Flower_Common_Poisoned2",
      "rotation": 5
    },
    {
      "x": 51,
      "y": 7,
      "z": 30,
      "name": "Empty"
    },
    {
      "x": 51,
      "y": 8,
      "z": 30,
      "name": "Empty"
    },
    {
      "x": 51,
      "y": 9,
      "z": 30,
      "name": "Empty"
    },
    {
      "x": 51,
      "y": 10,
      "z": 30,
      "name": "Empty"
    },
    {
      "x": 51,
      "y": 11,
      "z": 30,
      "name": "Empty"
    },
    {
      "x": 51,
      "y": 12,
      "z": 30,
      "name": "Plant_Crop_Mushroom_Block_Red_Trunk"
    },
    {
      "x": 51,
      "y": 13,
      "z": 30,
      "name": "Plant_Crop_Mushroom_Block_Red_Trunk"
    },
    {
      "x": 51,
      "y": 14,
      "z": 30,
      "name": "Empty"
    },
    {
      "x": 51,
      "y": 15,
      "z": 30,
      "name": "Empty"
    },
    {
      "x": 51,
      "y": 16,
      "z": 30,
      "name": "Empty"
    },
    {
      "x": 51,
      "y": 17,
      "z": 30,
      "name": "Empty"
    },
    {
      "x": 51,
      "y": 18,
      "z": 30,
      "name": "Empty"
    },
    {
      "x": 51,
      "y": 19,
      "z": 30,
      "name": "Empty"
    },
    {
      "x": 51,
      "y": 20,
      "z": 30,
      "name": "Rock_Basalt"
    },
    {
      "x": 51,
      "y": 21,
      "z": 30,
      "name": "Empty"
    },
    {
      "x": 51,
      "y": 22,
      "z": 30,
      "name": "Empty"
    },
    {
      "x": 51,
      "y": -9,
      "z": 31,
      "name": "Rock_Stone"
    },
    {
      "x": 51,
      "y": -8,
      "z": 31,
      "name": "Rock_Stone"
    },
    {
      "x": 51,
      "y": -7,
      "z": 31,
      "name": "Rock_Stone"
    },
    {
      "x": 51,
      "y": -6,
      "z": 31,
      "name": "Rock_Stone"
    },
    {
      "x": 51,
      "y": -5,
      "z": 31,
      "name": "Rock_Stone"
    },
    {
      "x": 51,
      "y": -4,
      "z": 31,
      "name": "Rock_Stone"
    },
    {
      "x": 51,
      "y": -3,
      "z": 31,
      "name": "Rock_Stone"
    },
    {
      "x": 51,
      "y": -2,
      "z": 31,
      "name": "Rock_Stone"
    },
    {
      "x": 51,
      "y": -1,
      "z": 31,
      "name": "Rock_Stone"
    },
    {
      "x": 51,
      "y": 0,
      "z": 31,
      "name": "Rock_Stone"
    },
    {
      "x": 51,
      "y": 1,
      "z": 31,
      "name": "Ore_Iron_Stone"
    },
    {
      "x": 51,
      "y": 2,
      "z": 31,
      "name": "Rock_Stone"
    },
    {
      "x": 51,
      "y": 3,
      "z": 31,
      "name": "Rock_Basalt_Cobble"
    },
    {
      "x": 51,
      "y": 4,
      "z": 31,
      "name": "Rock_Basalt_Cobble"
    },
    {
      "x": 51,
      "y": 5,
      "z": 31,
      "name": "Empty"
    },
    {
      "x": 51,
      "y": 6,
      "z": 31,
      "name": "Empty"
    },
    {
      "x": 51,
      "y": 7,
      "z": 31,
      "name": "Empty"
    },
    {
      "x": 51,
      "y": 8,
      "z": 31,
      "name": "Empty"
    },
    {
      "x": 51,
      "y": 9,
      "z": 31,
      "name": "Empty"
    },
    {
      "x": 51,
      "y": 10,
      "z": 31,
      "name": "Empty"
    },
    {
      "x": 51,
      "y": 11,
      "z": 31,
      "name": "Empty"
    },
    {
      "x": 51,
      "y": 12,
      "z": 31,
      "name": "Plant_Crop_Mushroom_Block_Red_Trunk"
    },
    {
      "x": 51,
      "y": 13,
      "z": 31,
      "name": "Empty"
    },
    {
      "x": 51,
      "y": 14,
      "z": 31,
      "name": "Empty"
    },
    {
      "x": 51,
      "y": 15,
      "z": 31,
      "name": "Empty"
    },
    {
      "x": 51,
      "y": 16,
      "z": 31,
      "name": "Empty"
    },
    {
      "x": 51,
      "y": 17,
      "z": 31,
      "name": "Empty"
    },
    {
      "x": 51,
      "y": 18,
      "z": 31,
      "name": "Empty"
    },
    {
      "x": 51,
      "y": 19,
      "z": 31,
      "name": "Empty"
    },
    {
      "x": 51,
      "y": 20,
      "z": 31,
      "name": "Rock_Stone"
    },
    {
      "x": 51,
      "y": 21,
      "z": 31,
      "name": "Empty"
    },
    {
      "x": 51,
      "y": 22,
      "z": 31,
      "name": "Empty"
    },
    {
      "x": 51,
      "y": -9,
      "z": 32,
      "name": "Rock_Stone"
    },
    {
      "x": 51,
      "y": -8,
      "z": 32,
      "name": "Rock_Stone"
    },
    {
      "x": 51,
      "y": -7,
      "z": 32,
      "name": "Rock_Stone"
    },
    {
      "x": 51,
      "y": -6,
      "z": 32,
      "name": "Rock_Stone"
    },
    {
      "x": 51,
      "y": -5,
      "z": 32,
      "name": "Rock_Stone"
    },
    {
      "x": 51,
      "y": -4,
      "z": 32,
      "name": "Rock_Stone"
    },
    {
      "x": 51,
      "y": -3,
      "z": 32,
      "name": "Rock_Stone"
    },
    {
      "x": 51,
      "y": -2,
      "z": 32,
      "name": "Rock_Stone"
    },
    {
      "x": 51,
      "y": -1,
      "z": 32,
      "name": "Rock_Stone"
    },
    {
      "x": 51,
      "y": 0,
      "z": 32,
      "name": "Rock_Stone"
    },
    {
      "x": 51,
      "y": 1,
      "z": 32,
      "name": "Rock_Stone"
    },
    {
      "x": 51,
      "y": 2,
      "z": 32,
      "name": "Rock_Stone"
    },
    {
      "x": 51,
      "y": 3,
      "z": 32,
      "name": "Rock_Basalt_Cobble"
    },
    {
      "x": 51,
      "y": 4,
      "z": 32,
      "name": "Soil_Gravel"
    },
    {
      "x": 51,
      "y": 5,
      "z": 32,
      "name": "Rock_Basalt_Cobble"
    },
    {
      "x": 51,
      "y": 6,
      "z": 32,
      "name": "Soil_Gravel"
    },
    {
      "x": 51,
      "y": 7,
      "z": 32,
      "name": "Rock_Basalt"
    },
    {
      "x": 51,
      "y": 8,
      "z": 32,
      "name": "Rock_Stone"
    },
    {
      "x": 51,
      "y": 9,
      "z": 32,
      "name": "Empty"
    },
    {
      "x": 51,
      "y": 10,
      "z": 32,
      "name": "Empty"
    },
    {
      "x": 51,
      "y": 11,
      "z": 32,
      "name": "Empty"
    },
    {
      "x": 51,
      "y": 12,
      "z": 32,
      "name": "Empty"
    },
    {
      "x": 51,
      "y": 13,
      "z": 32,
      "name": "Empty"
    },
    {
      "x": 51,
      "y": 14,
      "z": 32,
      "name": "Empty"
    },
    {
      "x": 51,
      "y": 15,
      "z": 32,
      "name": "Empty"
    },
    {
      "x": 51,
      "y": 16,
      "z": 32,
      "name": "Empty"
    },
    {
      "x": 51,
      "y": 17,
      "z": 32,
      "name": "Empty"
    },
    {
      "x": 51,
      "y": 18,
      "z": 32,
      "name": "Empty"
    },
    {
      "x": 51,
      "y": 19,
      "z": 32,
      "name": "Empty"
    },
    {
      "x": 51,
      "y": 20,
      "z": 32,
      "name": "Rock_Basalt"
    },
    {
      "x": 51,
      "y": 21,
      "z": 32,
      "name": "Empty"
    },
    {
      "x": 51,
      "y": 22,
      "z": 32,
      "name": "Empty"
    },
    {
      "x": 51,
      "y": -9,
      "z": 33,
      "name": "Rock_Stone"
    },
    {
      "x": 51,
      "y": -8,
      "z": 33,
      "name": "Rock_Stone"
    },
    {
